Workbook

Sheet Overview
A3: Model: | B3: 0.0.0.0
A4: Coin | B4: Pay Back
A5: 50 | B5: 0.96500663
A7: Total Pay Back Percentage includes the following adjustments.
A8: Coin | B8: Pay Back | C8: Hit% | D8: Pulls/Hit | E8: Description of feature
A9: 50 | B9: =[1]Card!AF62 -> 0.22842563 | C9: 0.0098234597 | D9: =1/C9 -> 101.79713 | E9: 新手
A10: 50 | B10: =[1]Card!AH62 -> 0.23294055 | C10: 0.0081862164 | D10: =1/C10 -> 122.15656 | E10: 老手
A13: Feature：
A14: 1. Base Game中，為[4,5,6,7,6,5,4]盤面。相同Symbol相連數量大於等於6連線後消除所有連線的標誌後，剩餘標誌往下掉落。 2. 初始盤面為Combo0，有連線消除後，變為Combo1+，並掉落新的標誌。 3. 中央固定為wild符號，當wild符號第二次得分時，這個位置會添加一個倍數，從 x2 開始，每次得分再 +2，上限為1000。 4. 每當符號得分的網格位置包含倍數時，得分為基本得分乘以網格倍數相互疊加。 5. 每一滾輪皆有機會出現C1，連線消除後也有機會出現C1，但若該轉輪已有C1，連線消除後該轉輪不會再出現C1。
A24: Pay Table： | B24: All wins show for 100 credit bet.
A26: Scatter Pay： | B26: C1 *
A27: 3 | B27: 0x
A28: 4 | B28: 0x
A29: 5 | B29: 0x
A30: 6 | B30: 0x
A31: 7 | B31: 0x
A32: *[C1]僅計算出現總數，對應倍數乘以押分。
B35: 6 | C35: 7 | D35: 8 | E35: 9 | F35: 10 | G35: 11 | H35: 12 | I35: 13 | J35: 14 | K35: 15+
A36: M1 | B36: 100 | C36: 200 | D36: 300 | E36: 500 | F36: 700 | G36: 1000 | H36: 1400 | I36: 3000 | J36: 4000 | K36: 5000
A37: M2 | B37: 60 | C37: 120 | D37: 160 | E37: 300 | F37: 400 | G37: 500 | H37: 600 | I37: 1100 | J37: 1200 | K37: 2000
A38: M3 | B38: 16 | C38: 20 | D38: 30 | E38: 100 | F38: 200 | G38: 400 | H38: 500 | I38: 700 | J38: 800 | K38: 1500
A39: M4 | B39: 16 | C39: 20 | D39: 30 | E39: 100 | F39: 200 | G39: 400 | H39: 500 | I39: 700 | J39: 800 | K39: 1500
A40: M5 | B40: 4 | C40: 10 | D40: 16 | E40: 60 | F40: 120 | G40: 200 | H40: 400 | I40: 550 | J40: 600 | K40: 1000
A41: M6 | B41: 4 | C41: 10 | D41: 16 | E41: 60 | F41: 120 | G41: 200 | H41: 400 | I41: 550 | J41: 600 | K41: 1000
A42: M7 | B42: 4 | C42: 10 | D42: 16 | E42: 60 | F42: 120 | G42: 200 | H42: 400 | I42: 550 | J42: 600 | K42: 1000

Sheet Description
B2: 1. 初始盤面(Combo 0)依照BaseGam權種Weights抽選輪帶按照BaseGameSymbol (Free Game Symbol) 中7個轉輪表和MY權重，決定初始盤面。
C4: BaseGame | D4: 權重 | F4: FreeGame | G4: 權重
C5: Initial 1 | D5: 900 | F5: Initial 1 | G5: 200
C6: Initial 2 | D6: 600 | F6: Initial 2 | G6: 600
C7: Initial 3 | D7: 600 | F7: Initial 3 | G7: 600
C8: Initial 4 | D8: 600 | F8: Initial 4 | G8: 800
C9: Initial 5 | D9: 800 | F9: Initial 5 | G9: 300
B11: 2. 所有符號均以至少 6個符號為一組進行連線得分，這些符號可以水平或垂直連接。遊戲在一個 [4,5,6,7,6,5,4]的符號網格上進行。
B13: 3. 中央符號固定為wild。當wild符號第二次得分時，這個位置會添加一個倍數，從 x2 開始，每次wild得分，倍數就會+2，直至最高 x1000。
B15: 4. 若有連線(此時變為Combo 1+)，則消除連線標誌後，剩餘標誌往下，依照消除數對應的(BaseDrop,FreeDrop,SuperFreeDrop)抽取掉落組合參數(同時消除複數個Symbol也只算一次消除)，然後抽取掉落方式(Random, Parallel),Random抽取為根據輪帶抽取權重Random Weights抽取7個轉輪表的掉落Symbol,Parallel為使用Parallel Weights抽取一個位置7個轉輪表共同使用。
C17: BaseDrop | D17: 1 | E17: 2 | F17: 3 | G17: 4 | H17: 5 | I17: 6 | J17: 7 | K17: 8 | L17: 9 | M17: 10+ | O17: FreeDrop | P17: 1 | Q17: 2 | R17: 3 | S17: 4 | T17: 5 | U17: 6 | V17: 7 | W17: 8 | X17: 9 | Y17: 10+
C18: Drop 1 | D18: 1000 | E18: 1000 | F18: 1000 | G18: 500 | H18: 500 | I18: 500 | J18: 10 | K18: 10 | L18: 10 | M18: 0 | O18: Drop 1 | P18: 300 | Q18: 300 | R18: 300 | S18: 100 | T18: 100 | U18: 100 | V18: 10 | W18: 10 | X18: 10 | Y18: 0
C19: Drop 2 | D19: 400 | E19: 400 | F19: 400 | G19: 200 | H19: 200 | I19: 200 | J19: 10 | K19: 10 | L19: 10 | M19: 0 | O19: Drop 2 | P19: 120 | Q19: 120 | R19: 120 | S19: 40 | T19: 40 | U19: 40 | V19: 10 | W19: 10 | X19: 10 | Y19: 0
C20: Drop 3 | D20: 1200 | E20: 1200 | F20: 1200 | G20: 600 | H20: 600 | I20: 600 | J20: 10 | K20: 10 | L20: 10 | M20: 0 | O20: Drop 3 | P20: 1200 | Q20: 1200 | R20: 1200 | S20: 240 | T20: 240 | U20: 240 | V20: 10 | W20: 10 | X20: 10 | Y20: 0
C21: Drop 4 | D21: 850 | E21: 0 | F21: 0 | G21: 0 | H21: 0 | I21: 0 | J21: 0 | K21: 0 | L21: 0 | M21: 0 | O21: Drop 4 | P21: 300 | Q21: 300 | R21: 300 | S21: 0 | T21: 0 | U21: 0 | V21: 0 | W21: 0 | X21: 0 | Y21: 0
C22: Drop 5 | D22: 1200 | E22: 1200 | F22: 1200 | G22: 600 | H22: 600 | I22: 600 | J22: 10 | K22: 10 | L22: 10 | M22: 0 | O22: Drop 5 | P22: 600 | Q22: 600 | R22: 600 | S22: 80 | T22: 80 | U22: 80 | V22: 10 | W22: 10 | X22: 10 | Y22: 0
C23: Drop 6 | D23: 951 | E23: 951 | F23: 951 | G23: 1500 | H23: 1500 | I23: 1500 | J23: 1155 | K23: 1155 | L23: 1155 | M23: 1100 | O23: Drop 6 | P23: 1300 | Q23: 1300 | R23: 1300 | S23: 1500 | T23: 1500 | U23: 1500 | V23: 1155 | W23: 1155 | X23: 1155 | Y23: 1100
B25: 4. 3個以上scatter觸發對應場次freegame和retrigger,一行最多出現一個C1，若在該行已存在C1的情況掉落新的C1，則將新的C1替換為MY1。
C27: Scatter | D27: 場次
C28: 3 | D28: 8
C29: 4 | D29: 10
C30: 5 | D30: 15
C31: 6 | D31: 20
C32: 7 | D32: 30
B34: 4.每當wild消除兩種符號，mega符號累計+1，上限為3，當畫面無法消除時，從Base Eliminate Symbol抽選mega符號轉換，放置對應數量的mega符號到盤面上，mega符號不可互相覆蓋，不可覆蓋到C1,wild上。
C36: Base Eliminate Symbol | D36: 權重 | G36: Free Eliminate Symbol | H36: 權重
C37: WW | D37: 0 | G37: WW | H37: 0
C38: C1 | D38: 0 | G38: C1 | H38: 0
C39: M1 | D39: 100 | G39: M1 | H39: 100
C40: M2 | D40: 110 | G40: M2 | H40: 110
C41: M3 | D41: 120 | G41: M3 | H41: 120
C42: M4 | D42: 150 | G42: M4 | H42: 150
C43: M5 | D43: 150 | G43: M5 | H43: 150
C44: M6 | D44: 180 | G44: M6 | H44: 180
C45: M7 | D45: 180 | G45: M7 | H45: 180
B48: 5. 當進行Buy Feature和Super Buy時,從Buy Feature Symbol進行盤面抽選，抽選完後根據BG Scatter權種決定Scatter數量，將對應數量隨機置換到盤面上(同一行不可出現2顆以上) , Base Game盤面Eliminate特色使用Buy Base Eliminate參數，進入Free Game後使用Free Eliminate參數。
C50: BG Scatter | D50: Feature | E50: Super Feature | H50: Buy Base Eliminate Symbol | I50: 權重
C51: 3 | D51: 1000 | E51: 1000 | H51: WW | I51: 0
C52: 4 | D52: 220 | E52: 220 | H52: C1 | I52: 0
C53: 5 | D53: 5 | E53: 5 | H53: M1 | I53: 100
...

Sheet 工作表1
A1: 0 | B1: 0.5 | C1: 0.5
A2: 1 | B2: 0.5 | C2: 0.5
A3: 2 | B3: 0.5 | C3: 0.5
A4: 3 | B4: 0.5 | C4: 0.5
A5: 4 | B5: 0.5 | C5: 0.5
A6: 5 | B6: 0.5 | C6: 0.5
A7: 6 | B7: 0.5 | C7: 0.5
A8: 7 | B8: 0.5 | C8: 0.5
A9: 8 | B9: 0.5 | C9: 0.5
A10: 9 | B10: 0.5 | C10: 0.5
A11: 10 | B11: 0.5 | C11: 0.5
A12: 15 | B12: 0.5 | C12: 0.5
... A57: 25000 | B57: 0.5 | C57: 0.5
B58: 0.5 | C58: 0.5

Sheet Card
AZ2: 新手(A) | BB2: 老手(A) | BD2: 新手 (EX)(A) | BF2: 老手 (EX)(A) | BH2: 新手(B) | BJ2: 老手(B) | BL2: 新手 (EX)(B) | BN2: 老手 (EX)(B)
A3: Lower | B3: Upper | C3: Simulator Cnt | F3: Simulator Pay | I3: Simulator Rate | L3: Simulator RTP | P3: Range | Q3: Base Game | AI3: Threshold | AQ3: =10^9 -> 1000000000 | AY3: Final RTP 1 | AZ3: =SUM(AY5:AY62)+AZ62*(SUM(AY67:AY125)) -> 1.8034641 | BA3: Final RTP 2 | BB3: =SUM(BA5:BA62)+BB62*(SUM(BA67:BA125)) -> 1.8055806 | BC3: Final RTP 3 | BD3: =SUM(BC5:BC62)+BD62*(SUM(BC67:BC125)) -> 2.241864 | BE3: Final RTP 4 | BF3: =SUM(BE5:BE62)+BF62*(SUM(BE67:BE125)) -> 2.2460393 | BG3: Final RTP 5 | BH3: =SUM(BG5:BG62)+BH62*(SUM(BG67:BG125)) -> 1.8034234 | BI3: Final RTP 6 | BJ3: =SUM(BI5:BI62)+BJ62*(SUM(BI67:BI125)) -> 1.8054681 | BK3: Final RTP 7 | BL3: =SUM(BK5:BK62)+BL62*(SUM(BK67:BK125)) -> 2.2418416 | BM3: Final RTP 8 | BN3: =SUM(BM5:BM62)+BN62*(SUM(BM67:BM125)) -> 2.2460283 | BQ3: 新手 | BR3: 老手1
C4: A | D4: B | E4: C | F4: A | G4: B | H4: C | I4: A | J4: B | K4: C | L4: A | M4: B | N4: C | Q4: 使用的表 | R4: Rate | S4: Fix Num 1 | T4: Fix Num 2 | U4: Fix Num 3 | V4: Fix Num 4 | W4: Fix Num 5 | X4: Fix Num 6 | Y4: Fix Num 7 | Z4: Fix Num 8 | AA4: Fix Rate 1 | AB4: Fix Rate 2 | AC4: Fix Rate 3 | AD4: Fix Rate 4 | AE4: Fix Num 5 | AF4: Fix Num 6 | AG4: Fix Num 7 | AH4: Fix Num 8 | AI4: Final Rate 1 | AJ4: Final Rate 2 | AK4: Final Rate 3 | AL4: Final Rate 4 | AM4: Final Rate 5 | AN4: Final Rate 6 | AO4: Final Rate 7 | AP4: Final Rate 8 | AQ4: Weight 1 | AR4: Weight 2 | AS4: Weight 3 | AT4: Weight 4 | AU4: Weight 5 | AV4: Weight 6 | AW4: Weight 7 | AX4: Weight 8 | AY4: Simulator RTP | AZ4: Hit Rate | BA4: Simulator RTP | BB4: Hit Rate | BC4: Simulator RTP | BD4: Hit Rate | BE4: Simulator RTP | BF4: Hit Rate | BG4: Simulator RTP | BH4: Hit Rate | BI4: Simulator RTP | BJ4: Hit Rate | BK4: Simulator RTP | BL4: Hit Rate | BM4: Simulator RTP | BN4: Hit Rate | BP4: Sugar Rush | BQ4: 調性1 | BR4: 調性2
A5: -1 | B5: 0 | C5: 47401554 | F5: 0 | I5: {=_xlfn.LET(_xlpm.x, C5:C61, _xlpm.x/SUM(_xlpm.x))} -> 0.48227795 | J5: {=_xlfn.LET(_xlpm.x, D5:D61, _xlpm.x/SUM(_xlpm.x))} -> #DIV/0! | L5: {=F5:F56/C5:C61/Overview!$A$5/5} -> 0 | M5: {=G5:G56/D5:D61/Overview!$A$5/5} -> #DIV/0! | P5: ="("&$A5&", "&$B5&"]" -> (-1, 0] | Q5: A | R5: =_xlfn.XLOOKUP(Q5, $I$4:$K$4, I5:K5) -> 0.48227795 | S5: 1 | T5: 1.3817774 | U5: 1 | V5: 1.4238 | W5: 1 | X5: 1.7 | Y5: 1 | Z5: 1.7 | AA5: {=$R5:$R62*S5:S62} -> 0.48227795 | AB5: {=$R5:$R62*T5:T62} -> 0.66640076 | AC5: {=$R5:$R62*U5:U62} -> 0.48227795 | AD5: {=$R5:$R62*V5:V62} -> 0.68666735 | AE5: {=$R5:$R62*W5:W62} -> 0.48227795 | AF5: {=$R5:$R62*X5:X62} -> 0.81987251 | AG5: {=$R5:$R62*Y5:Y62} -> 0.48227795 | AH5: {=$R5:$R62*Z5:Z62} -> 0.81987251 | AI5: {=AA5:AA61/SUM(_xlfn.ANCHORARRAY(AA5))} -> 0.6903104 | AJ5: {=AB5:AB61/SUM(_xlfn.ANCHORARRAY(AB5))} -> 0.65920829 | AK5: {=AC5:AC61/SUM(_xlfn.ANCHORARRAY(AC5))} -> 0.68872772 | AL5: {=AD5:AD61/SUM(_xlfn.ANCHORARRAY(AD5))} -> 0.6644678 | AM5: {=AE5:AE61/SUM(_xlfn.ANCHORARRAY(AE5))} -> 0.69459842 | AN5: {=AF5:AF61/SUM(_xlfn.ANCHORARRAY(AF5))} -> 0.69618814 | AO5: {=AG5:AG61/SUM(_xlfn.ANCHORARRAY(AG5))} -> 0.69518531 | AP5: {=AH5:AH61/SUM(_xlfn.ANCHORARRAY(AH5))} -> 0.69560007 | AQ5: =INT($AQ3-SUM(_xlfn.ANCHORARRAY(AQ6))) -> 691775284 | AR5: =INT($AQ3-SUM(_xlfn.ANCHORARRAY(AR6))) -> 659176226 | AS5: =INT($AQ3-SUM(_xlfn.ANCHORARRAY(AS6))) -> 691635190 | AT5: =INT($AQ3-SUM(_xlfn.ANCHORARRAY(AT6))) -> 664275682 | AU5: =INT($AQ3-SUM(_xlfn.ANCHORARRAY(AU6))) -> 696093499 | AV5: =INT($AQ3-SUM(_xlfn.ANCHORARRAY(AV6))) -> 695739870 | AW5: =INT($AQ3-SUM(_xlfn.ANCHORARRAY(AW6))) -> 698183724 | AX5: =INT($AQ3-SUM(_xlfn.ANCHORARRAY(AX6))) -> 694699271 | AY5: =_xlfn.LET(_xlpm.x, _xlfn.XLOOKUP($Q5, $L$4:$N$4, $L5:$N5), IF(ISERROR(_xlpm.x), 0, _xlpm.x)*AQ5/$AQ$3) -> 0 | AZ5: {=_xlfn.LET(_xlpm.x, AQ5:AQ62, _xlpm.x/SUM(_xlpm.x))} -> 0.69177528 | BA5: =_xlfn.LET(_xlpm.x, _xlfn.XLOOKUP($Q5, $L$4:$N$4, $L5:$N5), IF(ISERROR(_xlpm.x), 0, _xlpm.x)*AR5/$AQ$3) -> 0 | BB5: {=_xlfn.LET(_xlpm.x, AR5:AR62, _xlpm.x/SUM(_xlpm.x))} -> 0.65917623 | BC5: =_xlfn.LET(_xlpm.x, _xlfn.XLOOKUP($Q5, $L$4:$N$4, $L5:$N5), IF(ISERROR(_xlpm.x), 0, _xlpm.x)*AS5/$AQ$3) -> 0 | BD5: {=_xlfn.LET(_xlpm.x, AS5:AS62, _xlpm.x/SUM(_xlpm.x))} -> 0.69163519 | BE5: =_xlfn.LET(_xlpm.x, _xlfn.XLOOKUP($Q5, $L$4:$N$4, $L5:$N5), IF(ISERROR(_xlpm.x), 0, _xlpm.x)*AT5/$AQ$3) -> 0 | BF5: {=_xlfn.LET(_xlpm.x, AT5:AT62, _xlpm.x/SUM(_xlpm.x))} -> 0.66427568 | BG5: =_xlfn.LET(_xlpm.x, _xlfn.XLOOKUP($Q5, $L$4:$N$4, $L5:$N5), IF(ISERROR(_xlpm.x), 0, _xlpm.x)*AU5/$AQ$3) -> 0 | BH5: {=_xlfn.LET(_xlpm.x, AU5:AU62, _xlpm.x/SUM(_xlpm.x))} -> 0.6960935 | BI5: =_xlfn.LET(_xlpm.x, _xlfn.XLOOKUP($Q5, $L$4:$N$4, $L5:$N5), IF(ISERROR(_xlpm.x), 0, _xlpm.x)*AV5/$AQ$3) -> 0 | BJ5: {=_xlfn.LET(_xlpm.x, AV5:AV62, _xlpm.x/SUM(_xlpm.x))} -> 0.69573987 | BK5: =_xlfn.LET(_xlpm.x, _xlfn.XLOOKUP($Q5, $L$4:$N$4, $L5:$N5), IF(ISERROR(_xlpm.x), 0, _xlpm.x)*AW5/$AQ$3) -> 0 | BL5: {=_xlfn.LET(_xlpm.x, AW5:AW62, _xlpm.x/SUM(_xlpm.x))} -> 0.69818372 | BM5: =_xlfn.LET(_xlpm.x, _xlfn.XLOOKUP($Q5, $L$4:$N$4, $L5:$N5), IF(ISERROR(_xlpm.x), 0, _xlpm.x)*AX5/$AQ$3) -> 0 | BN5: {=_xlfn.LET(_xlpm.x, AX5:AX62, _xlpm.x/SUM(_xlpm.x))} -> 0.69469927 | BP5: 0.65880662 | BQ5: {=(1-AZ62)*AZ5:AZ56+AZ62*AZ67:AZ118} -> 0.68942602 | BR5: {=(1-BB62)*BB5:BB56+BB62*BB67:BB118} -> 0.65721748
A6: 0 | B6: 1 | C6: 17093477 | F6: 5054551150 | I6: 0.17391428 | J6: #DIV/0! | L6: 1.1828023 | M6: #DIV/0! | P6: ="("&$A6&", "&$B6&"]" -> (0, 1] | Q6: A | R6: =_xlfn.SINGLE(_xlfn.XLOOKUP(Q6, $I$4:$K$4, I6:K6)) -> 0.17391428 | S6: 0.5 | T6: 1.2892613 | U6: 0.5 | V6: 1.2892613 | W6: 0.5 | X6: 1.2892613 | Y6: 0.5 | Z6: 1.2892613 | AA6: 0.086957139 | AB6: 0.22422095 | AC6: 0.086957139 | AD6: 0.22422095 | AE6: 0.086957139 | AF6: 0.22422095 | AG6: 0.086957139 | AH6: 0.22422095 | AI6: 0.12446644 | AJ6: 0.22180093 | AK6: 0.12418107 | AL6: 0.21697202 | AM6: 0.12523959 | AN6: 0.19039541 | AO6: 0.12534541 | AP6: 0.19023458 | AQ6: {=INT(AI6:AI62*$AQ3)} -> 124466435 | AR6: {=INT(AJ6:AJ62*$AQ3)} -> 221800927 | AS6: {=INT(AK6:AK62*$AQ3)} -> 124181070 | AT6: {=INT(AL6:AL62*$AQ3)} -> 216972020 | AU6: {=INT(AM6:AM62*$AQ3)} -> 125239587 | AV6: {=INT(AN6:AN62*$AQ3)} -> 190395411 | AW6: {=INT(AO6:AO62*$AQ3)} -> 125345405 | AX6: {=INT(AP6:AP62*$AQ3)} -> 190234584 | AY6: =_xlfn.LET(_xlpm.x, _xlfn.XLOOKUP($Q6, $L$4:$N$4, $L6:$N6), IF(ISERROR(_xlpm.x), 0, _xlpm.x)*AQ6/$AQ$3) -> 0.14721919 | AZ6: 0.12446644 | BA6: =_xlfn.LET(_xlpm.x, _xlfn.XLOOKUP($Q6, $L$4:$N$4, $L6:$N6), IF(ISERROR(_xlpm.x), 0, _xlpm.x)*AR6/$AQ$3) -> 0.26234666 | BB6: 0.22180093 | BC6: =_xlfn.LET(_xlpm.x, _xlfn.XLOOKUP($Q6, $L$4:$N$4, $L6:$N6), IF(ISERROR(_xlpm.x), 0, _xlpm.x)*AS6/$AQ$3) -> 0.14688166 | BD6: 0.12418107 | BE6: =_xlfn.LET(_xlpm.x, _xlfn.XLOOKUP($Q6, $L$4:$N$4, $L6:$N6), IF(ISERROR(_xlpm.x), 0, _xlpm.x)*AT6/$AQ$3) -> 0.25663501 | BF6: 0.21697202 | BG6: =_xlfn.LET(_xlpm.x, _xlfn.XLOOKUP($Q6, $L$4:$N$4, $L6:$N6), IF(ISERROR(_xlpm.x), 0, _xlpm.x)*AU6/$AQ$3) -> 0.14813368 | BH6: 0.12523959 | BI6: =_xlfn.LET(_xlpm.x, _xlfn.XLOOKUP($Q6, $L$4:$N$4, $L6:$N6), IF(ISERROR(_xlpm.x), 0, _xlpm.x)*AV6/$AQ$3) -> 0.22520014 | BJ6: 0.19039541 | BK6: =_xlfn.LET(_xlpm.x, _xlfn.XLOOKUP($Q6, $L$4:$N$4, $L6:$N6), IF(ISERROR(_xlpm.x), 0, _xlpm.x)*AW6/$AQ$3) -> 0.14825884 | BL6: 0.1253454 | BM6: =_xlfn.LET(_xlpm.x, _xlfn.XLOOKUP($Q6, $L$4:$N$4, $L6:$N6), IF(ISERROR(_xlpm.x), 0, _xlpm.x)*AX6/$AQ$3) -> 0.22500991 | BN6: 0.19023458 | BP6: 0.22414436 | BQ6: 0.12404375 | BR6: 0.22114185
A7: 1 | B7: 2 | C7: 11621270 | F7: 8780093925 | I7: 0.11823837 | J7: #DIV/0! | L7: 3.0220773 | M7: #DIV/0! | P7: ="("&$A7&", "&$B7&"]" -> (1, 2] | Q7: A | R7: =_xlfn.SINGLE(_xlfn.XLOOKUP(Q7, $I$4:$K$4, I7:K7)) -> 0.11823837 | S7: 0.4 | T7: 0.49737495 | U7: 0.4 | V7: 0.49737495 | W7: 0.3 | X7: 0.49737495 | Y7: 0.3 | Z7: 0.49737495 | AA7: 0.047295346 | AB7: 0.058808801 | AC7: 0.047295346 | AD7: 0.058808801 | AE7: 0.03547151 | AF7: 0.058808801 | AG7: 0.03547151 | AH7: 0.058808801 | AI7: 0.067696376 | AJ7: 0.058174077 | AK7: 0.067541168 | AL7: 0.056907548 | AM7: 0.051087666 | AN7: 0.049937019 | AO7: 0.051130831 | AP7: 0.049894838 | AQ7: 67696375 | AR7: 58174076 | AS7: 67541167 | AT7: 56907547 | AU7: 51087665 | AV7: 49937019 | AW7: 51130830 | AX7: 49894837 | AY7: =_xlfn.LET(_xlpm.x, _xlfn.XLOOKUP($Q7, $L$4:$N$4, $L7:$N7), IF(ISERROR(_xlpm.x), 0, _xlpm.x)*AQ7/$AQ$3) -> 0.20458367 | AZ7: 0.067696375 | BA7: =_xlfn.LET(_xlpm.x, _xlfn.XLOOKUP($Q7, $L$4:$N$4, $L7:$N7), IF(ISERROR(_xlpm.x), 0, _xlpm.x)*AR7/$AQ$3) -> 0.17580655 | BB7: 0.058174076 | BC7: =_xlfn.LET(_xlpm.x, _xlfn.XLOOKUP($Q7, $L$4:$N$4, $L7:$N7), IF(ISERROR(_xlpm.x), 0, _xlpm.x)*AS7/$AQ$3) -> 0.20411462 | BD7: 0.067541167 | BE7: =_xlfn.LET(_xlpm.x, _xlfn.XLOOKUP($Q7, $L$4:$N$4, $L7:$N7), IF(ISERROR(_xlpm.x), 0, _xlpm.x)*AT7/$AQ$3) -> 0.171979 | BF7: 0.056907547 | BG7: =_xlfn.LET(_xlpm.x, _xlfn.XLOOKUP($Q7, $L$4:$N$4, $L7:$N7), IF(ISERROR(_xlpm.x), 0, _xlpm.x)*AU7/$AQ$3) -> 0.15439087 | BH7: 0.051087665 | BI7: =_xlfn.LET(_xlpm.x, _xlfn.XLOOKUP($Q7, $L$4:$N$4, $L7:$N7), IF(ISERROR(_xlpm.x), 0, _xlpm.x)*AV7/$AQ$3) -> 0.15091353 | BJ7: 0.049937019 | BK7: =_xlfn.LET(_xlpm.x, _xlfn.XLOOKUP($Q7, $L$4:$N$4, $L7:$N7), IF(ISERROR(_xlpm.x), 0, _xlpm.x)*AW7/$AQ$3) -> 0.15452132 | BL7: 0.05113083 | BM7: =_xlfn.LET(_xlpm.x, _xlfn.XLOOKUP($Q7, $L$4:$N$4, $L7:$N7), IF(ISERROR(_xlpm.x), 0, _xlpm.x)*AX7/$AQ$3) -> 0.15078605 | BN7: 0.049894837 | BP7: 0.05934955 | BQ7: 0.067466478 | BR7: 0.058043069
A8: 2 | B8: 3 | C8: 6640250 | F8: 8286213875 | I8: 0.06755994 | J8: #DIV/0! | L8: 4.9915072 | M8: #DIV/0! | P8: ="("&$A8&", "&$B8&"]" -> (2, 3] | Q8: A | R8: =_xlfn.SINGLE(_xlfn.XLOOKUP(Q8, $I$4:$K$4, I8:K8)) -> 0.06755994 | S8: 0.45 | T8: 0.26606414 | U8: 0.4295 | V8: 0.26606414 | W8: 0.45 | X8: 0.26606414 | Y8: 0.4 | Z8: 0.26606414 | AA8: 0.030401973 | AB8: 0.017975277 | AC8: 0.029016994 | AD8: 0.017975277 | AE8: 0.030401973 | AF8: 0.017975277 | AG8: 0.027023976 | AH8: 0.017975277 | AI8: 0.043515981 | AJ8: 0.01778127 | AK8: 0.041438362 | AL8: 0.017394147 | AM8: 0.043786291 | AN8: 0.015263562 | AO8: 0.038954033 | AP8: 0.015250669 | AQ8: 43515981 | AR8: 17781269 | AS8: 41438362 | AT8: 17394147 | AU8: 43786290 | AV8: 15263561 | AW8: 38954032 | AX8: 15250668 | AY8: =_xlfn.LET(_xlpm.x, _xlfn.XLOOKUP($Q8, $L$4:$N$4, $L8:$N8), IF(ISERROR(_xlpm.x), 0, _xlpm.x)*AQ8/$AQ$3) -> 0.21721033 | AZ8: 0.043515981 | BA8: =_xlfn.LET(_xlpm.x, _xlfn.XLOOKUP($Q8, $L$4:$N$4, $L8:$N8), IF(ISERROR(_xlpm.x), 0, _xlpm.x)*AR8/$AQ$3) -> 0.088755332 | BB8: 0.017781269 | BC8: =_xlfn.LET(_xlpm.x, _xlfn.XLOOKUP($Q8, $L$4:$N$4, $L8:$N8), IF(ISERROR(_xlpm.x), 0, _xlpm.x)*AS8/$AQ$3) -> 0.20683988 | BD8: 0.041438362 | BE8: =_xlfn.LET(_xlpm.x, _xlfn.XLOOKUP($Q8, $L$4:$N$4, $L8:$N8), IF(ISERROR(_xlpm.x), 0, _xlpm.x)*AT8/$AQ$3) -> 0.08682301 | BF8: 0.017394147 | BG8: =_xlfn.LET(_xlpm.x, _xlfn.XLOOKUP($Q8, $L$4:$N$4, $L8:$N8), IF(ISERROR(_xlpm.x), 0, _xlpm.x)*AU8/$AQ$3) -> 0.21855958 | BH8: 0.04378629 | BI8: =_xlfn.LET(_xlpm.x, _xlfn.XLOOKUP($Q8, $L$4:$N$4, $L8:$N8), IF(ISERROR(_xlpm.x), 0, _xlpm.x)*AV8/$AQ$3) -> 0.076188174 | BJ8: 0.015263561 | BK8: =_xlfn.LET(_xlpm.x, _xlfn.XLOOKUP($Q8, $L$4:$N$4, $L8:$N8), IF(ISERROR(_xlpm.x), 0, _xlpm.x)*AW8/$AQ$3) -> 0.19443933 | BL8: 0.038954032 | BM8: =_xlfn.LET(_xlpm.x, _xlfn.XLOOKUP($Q8, $L$4:$N$4, $L8:$N8), IF(ISERROR(_xlpm.x), 0, _xlpm.x)*AX8/$AQ$3) -> 0.076123819 | BN8: 0.015250668 | BP8: 0.018257306 | BQ8: 0.043368201 | BR8: 0.017770678
A9: 3 | B9: 4 | C9: 3771306 | F9: 6586601700 | I9: 0.038370424 | J9: #DIV/0! | L9: 6.9860167 | M9: #DIV/0! | P9: ="("&$A9&", "&$B9&"]" -> (3, 4] | Q9: A | R9: =_xlfn.SINGLE(_xlfn.XLOOKUP(Q9, $I$4:$K$4, I9:K9)) -> 0.038370424 | S9: 0.4925 | T9: 0.23983851 | U9: 0.5 | V9: 0.23983851 | W9: 0.4925 | X9: 0.23983851 | Y9: 0.4925 | Z9: 0.23983851 | AA9: 0.018897434 | AB9: 0.0092027052 | AC9: 0.019185212 | AD9: 0.0092027052 | AE9: 0.018897434 | AF9: 0.0092027052 | AG9: 0.018897434 | AH9: 0.0092027052 | AI9: 0.027048915 | AJ9: 0.0091033803 | AK9: 0.027397867 | AL9: 0.0089051873 | AM9: 0.027216935 | AN9: 0.007814403 | AO9: 0.027239932 | AP9: 0.0078078022 | AQ9: 27048914 | AR9: 9103380 | AS9: 27397867 | AT9: 8905187 | AU9: 27216935 | AV9: 7814402 | AW9: 27239931 | AX9: 7807802 | AY9: =_xlfn.LET(_xlpm.x, _xlfn.XLOOKUP($Q9, $L$4:$N$4, $L9:$N9), IF(ISERROR(_xlpm.x), 0, _xlpm.x)*AQ9/$AQ$3) -> 0.18896417 | AZ9: 0.027048914 | BA9: =_xlfn.LET(_xlpm.x, _xlfn.XLOOKUP($Q9, $L$4:$N$4, $L9:$N9), IF(ISERROR(_xlpm.x), 0, _xlpm.x)*AR9/$AQ$3) -> 0.063596365 | BB9: 0.00910338 | BC9: =_xlfn.LET(_xlpm.x, _xlfn.XLOOKUP($Q9, $L$4:$N$4, $L9:$N9), IF(ISERROR(_xlpm.x), 0, _xlpm.x)*AS9/$AQ$3) -> 0.19140196 | BD9: 0.027397867 | BE9: =_xlfn.LET(_xlpm.x, _xlfn.XLOOKUP($Q9, $L$4:$N$4, $L9:$N9), IF(ISERROR(_xlpm.x), 0, _xlpm.x)*AT9/$AQ$3) -> 0.062211785 | BF9: 0.008905187 | BG9: =_xlfn.LET(_xlpm.x, _xlfn.XLOOKUP($Q9, $L$4:$N$4, $L9:$N9), IF(ISERROR(_xlpm.x), 0, _xlpm.x)*AU9/$AQ$3) -> 0.19013796 | BH9: 0.027216935 | BI9: =_xlfn.LET(_xlpm.x, _xlfn.XLOOKUP($Q9, $L$4:$N$4, $L9:$N9), IF(ISERROR(_xlpm.x), 0, _xlpm.x)*AV9/$AQ$3) -> 0.054591543 | BJ9: 0.007814402 | BK9: =_xlfn.LET(_xlpm.x, _xlfn.XLOOKUP($Q9, $L$4:$N$4, $L9:$N9), IF(ISERROR(_xlpm.x), 0, _xlpm.x)*AW9/$AQ$3) -> 0.19029861 | BL9: 0.027239931 | BM9: =_xlfn.LET(_xlpm.x, _xlfn.XLOOKUP($Q9, $L$4:$N$4, $L9:$N9), IF(ISERROR(_xlpm.x), 0, _xlpm.x)*AX9/$AQ$3) -> 0.054545435 | BN9: 0.007807802 | BP9: 0.0093681801 | BQ9: 0.026957056 | BR9: 0.0091190428
A10: 4 | B10: 5 | C10: 2297819 | F10: 5168851175 | I10: 0.023378715 | J10: #DIV/0! | L10: 8.9978387 | M10: #DIV/0! | P10: ="("&$A10&", "&$B10&"]" -> (4, 5] | Q10: A | R10: =_xlfn.SINGLE(_xlfn.XLOOKUP(Q10, $I$4:$K$4, I10:K10)) -> 0.023378715 | S10: 0.5 | T10: 0.25695291 | U10: 0.5 | V10: 0.25695291 | W10: 0.7 | X10: 0.25695291 | Y10: 0.7 | Z10: 0.25695291 | AA10: 0.011689358 | AB10: 0.006007229 | AC10: 0.011689358 | AD10: 0.006007229 | AE10: 0.016365101 | AF10: 0.006007229 | AG10: 0.016365101 | AH10: 0.006007229 | AI10: 0.016731607 | AJ10: 0.0059423929 | AK10: 0.016693246 | AL10: 0.0058130189 | AM10: 0.023569755 | AN10: 0.0051009901 | AO10: 0.02358967 | AP10: 0.0050966813 | AQ10: 16731607 | AR10: 5942392 | AS10: 16693246 | AT10: 5813018 | AU10: 23569754 | AV10: 5100990 | AW10: 23589669 | AX10: 5096681 | AY10: =_xlfn.LET(_xlpm.x, _xlfn.XLOOKUP($Q10, $L$4:$N$4, $L10:$N10), IF(ISERROR(_xlpm.x), 0, _xlpm.x)*AQ10/$AQ$3) -> 0.1505483 | AZ10: 0.016731607 | BA10: =_xlfn.LET(_xlpm.x, _xlfn.XLOOKUP($Q10, $L$4:$N$4, $L10:$N10), IF(ISERROR(_xlpm.x), 0, _xlpm.x)*AR10/$AQ$3) -> 0.053468685 | BB10: 0.005942392 | BC10: =_xlfn.LET(_xlpm.x, _xlfn.XLOOKUP($Q10, $L$4:$N$4, $L10:$N10), IF(ISERROR(_xlpm.x), 0, _xlpm.x)*AS10/$AQ$3) -> 0.15020313 | BD10: 0.016693246 | BE10: =_xlfn.LET(_xlpm.x, _xlfn.XLOOKUP($Q10, $L$4:$N$4, $L10:$N10), IF(ISERROR(_xlpm.x), 0, _xlpm.x)*AT10/$AQ$3) -> 0.052304598 | BF10: 0.005813018 | BG10: =_xlfn.LET(_xlpm.x, _xlfn.XLOOKUP($Q10, $L$4:$N$4, $L10:$N10), IF(ISERROR(_xlpm.x), 0, _xlpm.x)*AU10/$AQ$3) -> 0.21207684 | BH10: 0.023569754 | BI10: =_xlfn.LET(_xlpm.x, _xlfn.XLOOKUP($Q10, $L$4:$N$4, $L10:$N10), IF(ISERROR(_xlpm.x), 0, _xlpm.x)*AV10/$AQ$3) -> 0.045897885 | BJ10: 0.00510099 | BK10: =_xlfn.LET(_xlpm.x, _xlfn.XLOOKUP($Q10, $L$4:$N$4, $L10:$N10), IF(ISERROR(_xlpm.x), 0, _xlpm.x)*AW10/$AQ$3) -> 0.21225604 | BL10: 0.023589669 | BM10: =_xlfn.LET(_xlpm.x, _xlfn.XLOOKUP($Q10, $L$4:$N$4, $L10:$N10), IF(ISERROR(_xlpm.x), 0, _xlpm.x)*AX10/$AQ$3) -> 0.045859113 | BN10: 0.005096681 | BP10: 0.0061212541 | BQ10: 0.016674786 | BR10: 0.005967411
A11: 5 | B11: 6 | C11: 1563754 | F11: 4304092200 | I11: 0.015910113 | J11: #DIV/0! | L11: 11.00964 | M11: #DIV/0! | P11: ="("&$A11&", "&$B11&"]" -> (5, 6] | Q11: A | R11: =_xlfn.SINGLE(_xlfn.XLOOKUP(Q11, $I$4:$K$4, I11:K11)) -> 0.015910113 | S11: 0.3 | T11: 0.22354049 | U11: 0.3 | V11: 0.22354049 | W11: 0.9105 | X11: 0.22354049 | Y11: 0.9 | Z11: 0.22354049 | AA11: 0.0047730339 | AB11: 0.0035565544 | AC11: 0.0047730339 | AD11: 0.0035565544 | AE11: 0.014486158 | AF11: 0.0035565544 | AG11: 0.014319102 | AH11: 0.0035565544 | AI11: 0.0068319004 | AJ11: 0.0035181685 | AK11: 0.0068162368 | AL11: 0.0034415732 | AM11: 0.020863617 | AN11: 0.0030200195 | AO11: 0.02064044 | AP11: 0.0030174685 | AQ11: 6831900 | AR11: 3518168 | AS11: 6816236 | AT11: 3441573 | AU11: 20863616 | AV11: 3020019 | AW11: 20640439 | AX11: 3017468 | AY11: =_xlfn.LET(_xlpm.x, _xlfn.XLOOKUP($Q11, $L$4:$N$4, $L11:$N11), IF(ISERROR(_xlpm.x), 0, _xlpm.x)*AQ11/$AQ$3) -> 0.07521676 | AZ11: 0.0068319 | BA11: =_xlfn.LET(_xlpm.x, _xlfn.XLOOKUP($Q11, $L$4:$N$4, $L11:$N11), IF(ISERROR(_xlpm.x), 0, _xlpm.x)*AR11/$AQ$3) -> 0.038733764 | BB11: 0.003518168 | BC11: =_xlfn.LET(_xlpm.x, _xlfn.XLOOKUP($Q11, $L$4:$N$4, $L11:$N11), IF(ISERROR(_xlpm.x), 0, _xlpm.x)*AS11/$AQ$3) -> 0.075044305 | BD11: 0.006816236 | BE11: =_xlfn.LET(_xlpm.x, _xlfn.XLOOKUP($Q11, $L$4:$N$4, $L11:$N11), IF(ISERROR(_xlpm.x), 0, _xlpm.x)*AT11/$AQ$3) -> 0.03789048 | BF11: 0.003441573 | BG11: =_xlfn.LET(_xlpm.x, _xlfn.XLOOKUP($Q11, $L$4:$N$4, $L11:$N11), IF(ISERROR(_xlpm.x), 0, _xlpm.x)*AU11/$AQ$3) -> 0.2297009 | BH11: 0.020863616 | BI11: =_xlfn.LET(_xlpm.x, _xlfn.XLOOKUP($Q11, $L$4:$N$4, $L11:$N11), IF(ISERROR(_xlpm.x), 0, _xlpm.x)*AV11/$AQ$3) -> 0.033249322 | BJ11: 0.003020019 | BK11: =_xlfn.LET(_xlpm.x, _xlfn.XLOOKUP($Q11, $L$4:$N$4, $L11:$N11), IF(ISERROR(_xlpm.x), 0, _xlpm.x)*AW11/$AQ$3) -> 0.22724381 | BL11: 0.020640439 | BM11: =_xlfn.LET(_xlpm.x, _xlfn.XLOOKUP($Q11, $L$4:$N$4, $L11:$N11), IF(ISERROR(_xlpm.x), 0, _xlpm.x)*AX11/$AQ$3) -> 0.033221237 | BN11: 0.003017468 | BP11: 0.0036195241 | BQ11: 0.0068086989 | BR11: 0.0035942556
A12: 6 | B12: 7 | C12: 1129414 | F12: 3674909250 | I12: 0.011491004 | J12: #DIV/0! | L12: 13.015278 | M12: #DIV/0! | P12: ="("&$A12&", "&$B12&"]" -> (6, 7] | Q12: A | R12: =_xlfn.SINGLE(_xlfn.XLOOKUP(Q12, $I$4:$K$4, I12:K12)) -> 0.011491004 | S12: 0.3 | T12: 0.24467549 | U12: 0.3 | V12: 0.24467549 | W12: 0.1 | X12: 0.2 | Y12: 0.1 | Z12: 0.2 | AA12: 0.0034473013 | AB12: 0.0028115671 | AC12: 0.0034473013 | AD12: 0.0028115671 | AE12: 0.0011491004 | AF12: 0.0022982009 | AG12: 0.0011491004 | AH12: 0.0022982009 | AI12: 0.004934308 | AJ12: 0.0027812218 | AK12: 0.0049229951 | AL12: 0.0027206709 | AM12: 0.0016549862 | AN12: 0.0019514988 | AO12: 0.0016563846 | AP12: 0.0019498503 | AQ12: 4934308 | AR12: 2781221 | AS12: 4922995 | AT12: 2720670 | AU12: 1654986 | AV12: 1951498 | AW12: 1656384 | AX12: 1949850 | AY12: =_xlfn.LET(_xlpm.x, _xlfn.XLOOKUP($Q12, $L$4:$N$4, $L12:$N12), IF(ISERROR(_xlpm.x), 0, _xlpm.x)*AQ12/$AQ$3) -> 0.06422139 | AZ12: 0.004934308 | BA12: =_xlfn.LET(_xlpm.x, _xlfn.XLOOKUP($Q12, $L$4:$N$4, $L12:$N12), IF(ISERROR(_xlpm.x), 0, _xlpm.x)*AR12/$AQ$3) -> 0.036198364 | BB12: 0.002781221 | BC12: =_xlfn.LET(_xlpm.x, _xlfn.XLOOKUP($Q12, $L$4:$N$4, $L12:$N12), IF(ISERROR(_xlpm.x), 0, _xlpm.x)*AS12/$AQ$3) -> 0.064074148 | BD12: 0.004922995 | BE12: =_xlfn.LET(_xlpm.x, _xlfn.XLOOKUP($Q12, $L$4:$N$4, $L12:$N12), IF(ISERROR(_xlpm.x), 0, _xlpm.x)*AT12/$AQ$3) -> 0.035410276 | BF12: 0.00272067 | BG12: =_xlfn.LET(_xlpm.x, _xlfn.XLOOKUP($Q12, $L$4:$N$4, $L12:$N12), IF(ISERROR(_xlpm.x), 0, _xlpm.x)*AU12/$AQ$3) -> 0.021540103 | BH12: 0.001654986 | BI12: =_xlfn.LET(_xlpm.x, _xlfn.XLOOKUP($Q12, $L$4:$N$4, $L12:$N12), IF(ISERROR(_xlpm.x), 0, _xlpm.x)*AV12/$AQ$3) -> 0.025399289 | BJ12: 0.001951498 | BK12: =_xlfn.LET(_xlpm.x, _xlfn.XLOOKUP($Q12, $L$4:$N$4, $L12:$N12), IF(ISERROR(_xlpm.x), 0, _xlpm.x)*AW12/$AQ$3) -> 0.021558298 | BL12: 0.001656384 | BM12: =_xlfn.LET(_xlpm.x, _xlfn.XLOOKUP($Q12, $L$4:$N$4, $L12:$N12), IF(ISERROR(_xlpm.x), 0, _xlpm.x)*AX12/$AQ$3) -> 0.025377839 | BN12: 0.00194985 | BP12: 0.002874328 | BQ12: 0.0049175511 | BR12: 0.0028153122
A13: 7 | B13: 8 | C13: 871364 | F13: 3273199000 | I13: 0.0088655246 | J13: #DIV/0! | L13: 15.025633 | M13: #DIV/0! | P13: ="("&$A13&", "&$B13&"]" -> (7, 8] | Q13: A | R13: =_xlfn.SINGLE(_xlfn.XLOOKUP(Q13, $I$4:$K$4, I13:K13)) -> 0.0088655246 | S13: 0.3 | T13: 0.29949353 | U13: 0.3 | V13: 0.29949353 | W13: 0.1 | X13: 0.25 | Y13: 0.1 | Z13: 0.25 | AA13: 0.0026596574 | AB13: 0.0026551673 | AC13: 0.0026596574 | AD13: 0.0026551673 | AE13: 0.00088655246 | AF13: 0.0022163812 | AG13: 0.00088655246 | AH13: 0.0022163812 | AI13: 0.0038069108 | AJ13: 0.00262651 | AK13: 0.0037981827 | AL13: 0.0025693273 | AM13: 0.0012768528 | AN13: 0.0018820222 | AO13: 0.0012779316 | AP13: 0.0018804325 | AQ13: 3806910 | AR13: 2626510 | AS13: 3798182 | AT13: 2569327 | AU13: 1276852 | AV13: 1882022 | AW13: 1277931 | AX13: 1880432 | AY13: =_xlfn.LET(_xlpm.x, _xlfn.XLOOKUP($Q13, $L$4:$N$4, $L13:$N13), IF(ISERROR(_xlpm.x), 0, _xlpm.x)*AQ13/$AQ$3) -> 0.057201234 | AZ13: 0.00380691 | BA13: =_xlfn.LET(_xlpm.x, _xlfn.XLOOKUP($Q13, $L$4:$N$4, $L13:$N13), IF(ISERROR(_xlpm.x), 0, _xlpm.x)*AR13/$AQ$3) -> 0.039464976 | BB13: 0.00262651 | BC13: =_xlfn.LET(_xlpm.x, _xlfn.XLOOKUP($Q13, $L$4:$N$4, $L13:$N13), IF(ISERROR(_xlpm.x), 0, _xlpm.x)*AS13/$AQ$3) -> 0.05707009 | BD13: 0.003798182 | BE13: =_xlfn.LET(_xlpm.x, _xlfn.XLOOKUP($Q13, $L$4:$N$4, $L13:$N13), IF(ISERROR(_xlpm.x), 0, _xlpm.x)*AT13/$AQ$3) -> 0.038605766 | BF13: 0.002569327 | BG13: =_xlfn.LET(_xlpm.x, _xlfn.XLOOKUP($Q13, $L$4:$N$4, $L13:$N13), IF(ISERROR(_xlpm.x), 0, _xlpm.x)*AU13/$AQ$3) -> 0.01918551 | BH13: 0.001276852 | BI13: =_xlfn.LET(_xlpm.x, _xlfn.XLOOKUP($Q13, $L$4:$N$4, $L13:$N13), IF(ISERROR(_xlpm.x), 0, _xlpm.x)*AV13/$AQ$3) -> 0.028278573 | BJ13: 0.001882022 | BK13: =_xlfn.LET(_xlpm.x, _xlfn.XLOOKUP($Q13, $L$4:$N$4, $L13:$N13), IF(ISERROR(_xlpm.x), 0, _xlpm.x)*AW13/$AQ$3) -> 0.019201723 | BL13: 0.001277931 | BM13: =_xlfn.LET(_xlpm.x, _xlfn.XLOOKUP($Q13, $L$4:$N$4, $L13:$N13), IF(ISERROR(_xlpm.x), 0, _xlpm.x)*AX13/$AQ$3) -> 0.028254682 | BN13: 0.001880432 | BP13: 0.0027146431 | BQ13: 0.0037939817 | BR13: 0.0026624334
A14: 8 | B14: 9 | C14: 693599 | F14: 2952383725 | I14: 0.007056889 | J14: #DIV/0! | L14: 17.026459 | M14: #DIV/0! | P14: ="("&$A14&", "&$B14&"]" -> (8, 9] | Q14: A | R14: =_xlfn.SINGLE(_xlfn.XLOOKUP(Q14, $I$4:$K$4, I14:K14)) -> 0.007056889 | S14: 0.3 | T14: 0.26555853 | U14: 0.3 | V14: 0.26555853 | W14: 0.1 | X14: 0.5 | Y14: 0.1 | Z14: 0.5 | AA14: 0.0021170667 | AB14: 0.0018740171 | AC14: 0.0021170667 | AD14: 0.0018740171 | AE14: 0.0007056889 | AF14: 0.0035284445 | AG14: 0.0007056889 | AH14: 0.0035284445 | AI14: 0.0030302716 | AJ14: 0.0018537908 | AK14: 0.003023324 | AL14: 0.0018134312 | AM14: 0.0010163649 | AN14: 0.0029961502 | AO14: 0.0010172237 | AP14: 0.0029936194 | AQ14: 3030271 | AR14: 1853790 | AS14: 3023324 | AT14: 1813431 | AU14: 1016364 | AV14: 2996150 | AW14: 1017223 | AX14: 2993619 | AY14: =_xlfn.LET(_xlpm.x, _xlfn.XLOOKUP($Q14, $L$4:$N$4, $L14:$N14), IF(ISERROR(_xlpm.x), 0, _xlpm.x)*AQ14/$AQ$3) -> 0.051594785 | AZ14: 0.003030271 | BA14: =_xlfn.LET(_xlpm.x, _xlfn.XLOOKUP($Q14, $L$4:$N$4, $L14:$N14), IF(ISERROR(_xlpm.x), 0, _xlpm.x)*AR14/$AQ$3) -> 0.031563479 | BB14: 0.00185379 | BC14: =_xlfn.LET(_xlpm.x, _xlfn.XLOOKUP($Q14, $L$4:$N$4, $L14:$N14), IF(ISERROR(_xlpm.x), 0, _xlpm.x)*AS14/$AQ$3) -> 0.051476502 | BD14: 0.003023324 | BE14: =_xlfn.LET(_xlpm.x, _xlfn.XLOOKUP($Q14, $L$4:$N$4, $L14:$N14), IF(ISERROR(_xlpm.x), 0, _xlpm.x)*AT14/$AQ$3) -> 0.030876308 | BF14: 0.001813431 | BG14: =_xlfn.LET(_xlpm.x, _xlfn.XLOOKUP($Q14, $L$4:$N$4, $L14:$N14), IF(ISERROR(_xlpm.x), 0, _xlpm.x)*AU14/$AQ$3) -> 0.01730508 | BH14: 0.001016364 | BI14: =_xlfn.LET(_xlpm.x, _xlfn.XLOOKUP($Q14, $L$4:$N$4, $L14:$N14), IF(ISERROR(_xlpm.x), 0, _xlpm.x)*AV14/$AQ$3) -> 0.051013825 | BJ14: 0.00299615 | BK14: =_xlfn.LET(_xlpm.x, _xlfn.XLOOKUP($Q14, $L$4:$N$4, $L14:$N14), IF(ISERROR(_xlpm.x), 0, _xlpm.x)*AW14/$AQ$3) -> 0.017319706 | BL14: 0.001017223 | BM14: =_xlfn.LET(_xlpm.x, _xlfn.XLOOKUP($Q14, $L$4:$N$4, $L14:$N14), IF(ISERROR(_xlpm.x), 0, _xlpm.x)*AX14/$AQ$3) -> 0.050970731 | BN14: 0.002993619 | BP14: 0.0019162187 | BQ14: 0.0030199802 | BR14: 0.0019351032
A15: 9 | B15: 10 | C15: 563083 | F15: 2679549175 | I15: 0.0057289792 | J15: #DIV/0! | L15: 19.034843 | M15: #DIV/0! | P15: ="("&$A15&", "&$B15&"]" -> (9, 10] | Q15: A | R15: =_xlfn.SINGLE(_xlfn.XLOOKUP(Q15, $I$4:$K$4, I15:K15)) -> 0.0057289792 | S15: 0.2 | T15: 0.2545739 | U15: 0.2 | V15: 0.2545739 | W15: 0.1 | X15: 1.1 | Y15: 0.1 | Z15: 1.1 | AA15: 0.0011457958 | AB15: 0.0014584486 | AC15: 0.0011457958 | AD15: 0.0014584486 | AE15: 0.00057289792 | AF15: 0.0063018771 | AG15: 0.00057289792 | AH15: 0.0063018771 | AI15: 0.0016400393 | AJ15: 0.0014427075 | AK15: 0.0016362791 | AL15: 0.0014112978 | AM15: 0.00082511338 | AN15: 0.0053511881 | AO15: 0.00082581054 | AP15: 0.005346668 | AQ15: 1640039 | AR15: 1442707 | AS15: 1636279 | AT15: 1411297 | AU15: 825113 | AV15: 5351188 | AW15: 825810 | AX15: 5346667 | AY15: =_xlfn.LET(_xlpm.x, _xlfn.XLOOKUP($Q15, $L$4:$N$4, $L15:$N15), IF(ISERROR(_xlpm.x), 0, _xlpm.x)*AQ15/$AQ$3) -> 0.031217885 | AZ15: 0.001640039 | BA15: =_xlfn.LET(_xlpm.x, _xlfn.XLOOKUP($Q15, $L$4:$N$4, $L15:$N15), IF(ISERROR(_xlpm.x), 0, _xlpm.x)*AR15/$AQ$3) -> 0.027461702 | BB15: 0.001442707 | BC15: =_xlfn.LET(_xlpm.x, _xlfn.XLOOKUP($Q15, $L$4:$N$4, $L15:$N15), IF(ISERROR(_xlpm.x), 0, _xlpm.x)*AS15/$AQ$3) -> 0.031146314 | BD15: 0.001636279 | BE15: =_xlfn.LET(_xlpm.x, _xlfn.XLOOKUP($Q15, $L$4:$N$4, $L15:$N15), IF(ISERROR(_xlpm.x), 0, _xlpm.x)*AT15/$AQ$3) -> 0.026863817 | BF15: 0.001411297 | BG15: =_xlfn.LET(_xlpm.x, _xlfn.XLOOKUP($Q15, $L$4:$N$4, $L15:$N15), IF(ISERROR(_xlpm.x), 0, _xlpm.x)*AU15/$AQ$3) -> 0.015705897 | BH15: 0.000825113 | BI15: =_xlfn.LET(_xlpm.x, _xlfn.XLOOKUP($Q15, $L$4:$N$4, $L15:$N15), IF(ISERROR(_xlpm.x), 0, _xlpm.x)*AV15/$AQ$3) -> 0.10185903 | BJ15: 0.005351188 | BK15: =_xlfn.LET(_xlpm.x, _xlfn.XLOOKUP($Q15, $L$4:$N$4, $L15:$N15), IF(ISERROR(_xlpm.x), 0, _xlpm.x)*AW15/$AQ$3) -> 0.015719164 | BL15: 0.00082581 | BM15: =_xlfn.LET(_xlpm.x, _xlfn.XLOOKUP($Q15, $L$4:$N$4, $L15:$N15), IF(ISERROR(_xlpm.x), 0, _xlpm.x)*AX15/$AQ$3) -> 0.10177297 | BN15: 0.005346667 | BP15: 0.0014903923 | BQ15: 0.0016344694 | BR15: 0.0017858425
A16: 10 | B16: 15 | C16: 1760734 | F16: 10750786875 | I16: 0.017914248 | J16: #DIV/0! | L16: 24.423421 | M16: #DIV/0! | P16: ="("&$A16&", "&$B16&"]" -> (10, 15] | Q16: A | R16: =_xlfn.SINGLE(_xlfn.XLOOKUP(Q16, $I$4:$K$4, I16:K16)) -> 0.017914248 | S16: 0.1452 | T16: 0.405 | U16: 0.12 | V16: 0.3942 | W16: 0.154 | X16: 0.682 | Y16: 0.1296 | Z16: 0.6 | AA16: 0.0026011488 | AB16: 0.0072552704 | AC16: 0.0021497097 | AD16: 0.0070617965 | AE16: 0.0027587942 | AF16: 0.012217517 | AG16: 0.0023216865 | AH16: 0.010748549 | AI16: 0.0037231643 | AJ16: 0.0071769641 | AK16: 0.0030699406 | AL16: 0.0068334929 | AM16: 0.0039733396 | AN16: 0.010374406 | AO16: 0.0033466227 | AP16: 0.0091193339 | AQ16: 3723164 | AR16: 7176964 | AS16: 3069940 | AT16: 6833492 | AU16: 3973339 | AV16: 10374406 | AW16: 3346622 | AX16: 9119333 | AY16: =_xlfn.LET(_xlpm.x, _xlfn.XLOOKUP($Q16, $L$4:$N$4, $L16:$N16), IF(ISERROR(_xlpm.x), 0, _xlpm.x)*AQ16/$AQ$3) -> 0.090932401 | AZ16: 0.003723164 | BA16: =_xlfn.LET(_xlpm.x, _xlfn.XLOOKUP($Q16, $L$4:$N$4, $L16:$N16), IF(ISERROR(_xlpm.x), 0, _xlpm.x)*AR16/$AQ$3) -> 0.17528601 | BB16: 0.007176964 | BC16: =_xlfn.LET(_xlpm.x, _xlfn.XLOOKUP($Q16, $L$4:$N$4, $L16:$N16), IF(ISERROR(_xlpm.x), 0, _xlpm.x)*AS16/$AQ$3) -> 0.074978437 | BD16: 0.00306994 | BE16: =_xlfn.LET(_xlpm.x, _xlfn.XLOOKUP($Q16, $L$4:$N$4, $L16:$N16), IF(ISERROR(_xlpm.x), 0, _xlpm.x)*AT16/$AQ$3) -> 0.16689725 | BF16: 0.006833492 | BG16: =_xlfn.LET(_xlpm.x, _xlfn.XLOOKUP($Q16, $L$4:$N$4, $L16:$N16), IF(ISERROR(_xlpm.x), 0, _xlpm.x)*AU16/$AQ$3) -> 0.097042531 | BH16: 0.003973339 | BI16: =_xlfn.LET(_xlpm.x, _xlfn.XLOOKUP($Q16, $L$4:$N$4, $L16:$N16), IF(ISERROR(_xlpm.x), 0, _xlpm.x)*AV16/$AQ$3) -> 0.25337848 | BJ16: 0.010374406 | BK16: =_xlfn.LET(_xlpm.x, _xlfn.XLOOKUP($Q16, $L$4:$N$4, $L16:$N16), IF(ISERROR(_xlpm.x), 0, _xlpm.x)*AW16/$AQ$3) -> 0.081735958 | BL16: 0.003346622 | BM16: =_xlfn.LET(_xlpm.x, _xlfn.XLOOKUP($Q16, $L$4:$N$4, $L16:$N16), IF(ISERROR(_xlpm.x), 0, _xlpm.x)*AX16/$AQ$3) -> 0.22272531 | BN16: 0.009119333 | BP16: 0.0056954277 | BQ16: 0.0037105201 | BR16: 0.0074599726
A17: 15 | B17: 20 | C17: 874110 | F17: 7545290800 | I17: 0.0088934633 | J17: #DIV/0! | L17: 34.527878 | M17: #DIV/0! | P17: ="("&$A17&", "&$B17&"]" -> (15, 20] | Q17: A | R17: =_xlfn.SINGLE(_xlfn.XLOOKUP(Q17, $I$4:$K$4, I17:K17)) -> 0.0088934633 | S17: 0.1102 | T17: 0.23318795 | U17: 0.083 | V17: 0.2 | W17: 0 | X17: 0.8 | Y17: 0 | Z17: 0.743 | AA17: 0.00098005965 | AB17: 0.0020738484 | AC17: 0.00073815745 | AD17: 0.0017786927 | AE17: 0 | AF17: 0.0071147706 | AG17: 0 | AH17: 0.0066078432 | AI17: 0.0014028122 | AJ17: 0.0020514654 | AK17: 0.0010541421 | AL17: 0.0017211886 | AM17: 0 | AN17: 0.0060414501 | AO17: 0 | AP17: 0.0056062572 | AQ17: 1402812 | AR17: 2051465 | AS17: 1054142 | AT17: 1721188 | AU17: 0 | AV17: 6041450 | AW17: 0 | AX17: 5606257 | AY17: =_xlfn.LET(_xlpm.x, _xlfn.XLOOKUP($Q17, $L$4:$N$4, $L17:$N17), IF(ISERROR(_xlpm.x), 0, _xlpm.x)*AQ17/$AQ$3) -> 0.048436121 | AZ17: 0.001402812 | BA17: =_xlfn.LET(_xlpm.x, _xlfn.XLOOKUP($Q17, $L$4:$N$4, $L17:$N17), IF(ISERROR(_xlpm.x), 0, _xlpm.x)*AR17/$AQ$3) -> 0.070832733 | BB17: 0.002051465 | BC17: =_xlfn.LET(_xlpm.x, _xlfn.XLOOKUP($Q17, $L$4:$N$4, $L17:$N17), IF(ISERROR(_xlpm.x), 0, _xlpm.x)*AS17/$AQ$3) -> 0.036397286 | BD17: 0.001054142 | BE17: =_xlfn.LET(_xlpm.x, _xlfn.XLOOKUP($Q17, $L$4:$N$4, $L17:$N17), IF(ISERROR(_xlpm.x), 0, _xlpm.x)*AT17/$AQ$3) -> 0.059428969 | BF17: 0.001721188 | BG17: =_xlfn.LET(_xlpm.x, _xlfn.XLOOKUP($Q17, $L$4:$N$4, $L17:$N17), IF(ISERROR(_xlpm.x), 0, _xlpm.x)*AU17/$AQ$3) -> 0 | BH17: 0 | BI17: =_xlfn.LET(_xlpm.x, _xlfn.XLOOKUP($Q17, $L$4:$N$4, $L17:$N17), IF(ISERROR(_xlpm.x), 0, _xlpm.x)*AV17/$AQ$3) -> 0.20859845 | BJ17: 0.00604145 | BK17: =_xlfn.LET(_xlpm.x, _xlfn.XLOOKUP($Q17, $L$4:$N$4, $L17:$N17), IF(ISERROR(_xlpm.x), 0, _xlpm.x)*AW17/$AQ$3) -> 0 | BL17: 0 | BM17: =_xlfn.LET(_xlpm.x, _xlfn.XLOOKUP($Q17, $L$4:$N$4, $L17:$N17), IF(ISERROR(_xlpm.x), 0, _xlpm.x)*AX17/$AQ$3) -> 0.19357216 | BN17: 0.005606257 | BP17: 0.0021291318 | BQ17: 0.0013980481 | BR17: 0.0021339122
A18: 20 | B18: 25 | C18: 518006 | F18: 5776645850 | I18: 0.0052703519 | J18: #DIV/0! | L18: 44.606787 | M18: #DIV/0! | P18: ="("&$A18&", "&$B18&"]" -> (20, 25] | Q18: A | R18: =_xlfn.SINGLE(_xlfn.XLOOKUP(Q18, $I$4:$K$4, I18:K18)) -> 0.0052703519 | S18: 0 | T18: 0.21557591 | U18: 0 | V18: 0.2 | W18: 0 | X18: 0.1 | Y18: 0 | Z18: 0.1 | AA18: 0 | AB18: 0.0011361609 | AC18: 0 | AD18: 0.0010540704 | AE18: 0 | AF18: 0.00052703519 | AG18: 0 | AH18: 0.00052703519 | AI18: 0 | AJ18: 0.0011238983 | AK18: 0 | AL18: 0.0010199929 | AM18: 0 | AN18: 0.00044752769 | AO18: 0 | AP18: 0.00044714966 | AQ18: 0 | AR18: 1123898 | AS18: 0 | AT18: 1019992 | AU18: 0 | AV18: 447527 | AW18: 0 | AX18: 447149 | AY18: =_xlfn.LET(_xlpm.x, _xlfn.XLOOKUP($Q18, $L$4:$N$4, $L18:$N18), IF(ISERROR(_xlpm.x), 0, _xlpm.x)*AQ18/$AQ$3) -> 0 | AZ18: 0 | BA18: =_xlfn.LET(_xlpm.x, _xlfn.XLOOKUP($Q18, $L$4:$N$4, $L18:$N18), IF(ISERROR(_xlpm.x), 0, _xlpm.x)*AR18/$AQ$3) -> 0.050133479 | BB18: 0.001123898 | BC18: =_xlfn.LET(_xlpm.x, _xlfn.XLOOKUP($Q18, $L$4:$N$4, $L18:$N18), IF(ISERROR(_xlpm.x), 0, _xlpm.x)*AS18/$AQ$3) -> 0 | BD18: 0 | BE18: =_xlfn.LET(_xlpm.x, _xlfn.XLOOKUP($Q18, $L$4:$N$4, $L18:$N18), IF(ISERROR(_xlpm.x), 0, _xlpm.x)*AT18/$AQ$3) -> 0.045498566 | BF18: 0.001019992 | BG18: =_xlfn.LET(_xlpm.x, _xlfn.XLOOKUP($Q18, $L$4:$N$4, $L18:$N18), IF(ISERROR(_xlpm.x), 0, _xlpm.x)*AU18/$AQ$3) -> 0 | BH18: 0 | BI18: =_xlfn.LET(_xlpm.x, _xlfn.XLOOKUP($Q18, $L$4:$N$4, $L18:$N18), IF(ISERROR(_xlpm.x), 0, _xlpm.x)*AV18/$AQ$3) -> 0.019962742 | BJ18: 0.000447527 | BK18: =_xlfn.LET(_xlpm.x, _xlfn.XLOOKUP($Q18, $L$4:$N$4, $L18:$N18), IF(ISERROR(_xlpm.x), 0, _xlpm.x)*AW18/$AQ$3) -> 0 | BL18: 0 | BM18: =_xlfn.LET(_xlpm.x, _xlfn.XLOOKUP($Q18, $L$4:$N$4, $L18:$N18), IF(ISERROR(_xlpm.x), 0, _xlpm.x)*AX18/$AQ$3) -> 0.01994588 | BN18: 0.000447149 | BP18: 0.0011710225 | BQ18: 0 | BR18: 0.0012093016
... A56: 7000 | B56: 8000 | C56: 25 | F56: 93668975 | I56: 2.5435767e-07 | J56: #DIV/0! | L56: 14987.036 | M56: #DIV/0! | P56: ="("&$A56&", "&$B56&"]" -> (7000, 8000] | Q56: A | R56: =_xlfn.SINGLE(_xlfn.XLOOKUP(Q56, $I$4:$K$4, I56:K56)) -> 2.5435767e-07 | S56: 0 | T56: 0 | U56: 0 | V56: 0 | W56: 0 | X56: 0 | Y56: 0 | Z56: 0 | AA56: 0 | AB56: 0 | AC56: 0 | AD56: 0 | AE56: 0 | AF56: 0 | AG56: 0 | AH56: 0 | AI56: 0 | AJ56: 0 | AK56: 0 | AL56: 0 | AM56: 0 | AN56: 0 | AO56: 0 | AP56: 0 | AQ56: 0 | AR56: 0 | AS56: 0 | AT56: 0 | AU56: 0 | AV56: 0 | AW56: 0 | AX56: 0 | AY56: =_xlfn.LET(_xlpm.x, _xlfn.XLOOKUP($Q56, $L$4:$N$4, $L56:$N56), IF(ISERROR(_xlpm.x), 0, _xlpm.x)*AQ56/$AQ$3) -> 0 | AZ56: 0 | BA56: =_xlfn.LET(_xlpm.x, _xlfn.XLOOKUP($Q56, $L$4:$N$4, $L56:$N56), IF(ISERROR(_xlpm.x), 0, _xlpm.x)*AR56/$AQ$3) -> 0 | BB56: 0 | BC56: =_xlfn.LET(_xlpm.x, _xlfn.XLOOKUP($Q56, $L$4:$N$4, $L56:$N56), IF(ISERROR(_xlpm.x), 0, _xlpm.x)*AS56/$AQ$3) -> 0 | BD56: 0 | BE56: =_xlfn.LET(_xlpm.x, _xlfn.XLOOKUP($Q56, $L$4:$N$4, $L56:$N56), IF(ISERROR(_xlpm.x), 0, _xlpm.x)*AT56/$AQ$3) -> 0 | BF56: 0 | BG56: =_xlfn.LET(_xlpm.x, _xlfn.XLOOKUP($Q56, $L$4:$N$4, $L56:$N56), IF(ISERROR(_xlpm.x), 0, _xlpm.x)*AU56/$AQ$3) -> 0 | BH56: 0 | BI56: =_xlfn.LET(_xlpm.x, _xlfn.XLOOKUP($Q56, $L$4:$N$4, $L56:$N56), IF(ISERROR(_xlpm.x), 0, _xlpm.x)*AV56/$AQ$3) -> 0 | BJ56: 0 | BK56: =_xlfn.LET(_xlpm.x, _xlfn.XLOOKUP($Q56, $L$4:$N$4, $L56:$N56), IF(ISERROR(_xlpm.x), 0, _xlpm.x)*AW56/$AQ$3) -> 0 | BL56: 0 | BM56: =_xlfn.LET(_xlpm.x, _xlfn.XLOOKUP($Q56, $L$4:$N$4, $L56:$N56), IF(ISERROR(_xlpm.x), 0, _xlpm.x)*AX56/$AQ$3) -> 0 | BN56: 0 | BP56: 0 | BQ56: 0 | BR56: 0
A57: 8000 | B57: 9000 | C57: 13 | F57: 54711325 | I57: 1.3226599e-07 | J57: #DIV/0! | L57: #N/A | M57: #N/A | P57: ="("&$A57&", "&$B57&"]" -> (8000, 9000] | Q57: A | R57: =_xlfn.SINGLE(_xlfn.XLOOKUP(Q57, $I$4:$K$4, I57:K57)) -> 1.3226599e-07 | S57: 0 | T57: 0 | U57: 0 | V57: 0 | W57: 0 | X57: 0 | Y57: 0 | Z57: 0 | AA57: 0 | AB57: 0 | AC57: 0 | AD57: 0 | AE57: 0 | AF57: 0 | AG57: 0 | AH57: 0 | AI57: 0 | AJ57: 0 | AK57: 0 | AL57: 0 | AM57: 0 | AN57: 0 | AO57: 0 | AP57: 0 | AQ57: 0 | AR57: 0 | AS57: 0 | AT57: 0 | AU57: 0 | AV57: 0 | AW57: 0 | AX57: 0 | AY57: =_xlfn.LET(_xlpm.x, _xlfn.XLOOKUP($Q57, $L$4:$N$4, $L57:$N57), IF(ISERROR(_xlpm.x), 0, _xlpm.x)*AQ57/$AQ$3) -> 0 | AZ57: 0 | BA57: =_xlfn.LET(_xlpm.x, _xlfn.XLOOKUP($Q57, $L$4:$N$4, $L57:$N57), IF(ISERROR(_xlpm.x), 0, _xlpm.x)*AR57/$AQ$3) -> 0 | BB57: 0 | BC57: =_xlfn.LET(_xlpm.x, _xlfn.XLOOKUP($Q57, $L$4:$N$4, $L57:$N57), IF(ISERROR(_xlpm.x), 0, _xlpm.x)*AS57/$AQ$3) -> 0 | BD57: 0 | BE57: =_xlfn.LET(_xlpm.x, _xlfn.XLOOKUP($Q57, $L$4:$N$4, $L57:$N57), IF(ISERROR(_xlpm.x), 0, _xlpm.x)*AT57/$AQ$3) -> 0 | BF57: 0 | BG57: =_xlfn.LET(_xlpm.x, _xlfn.XLOOKUP($Q57, $L$4:$N$4, $L57:$N57), IF(ISERROR(_xlpm.x), 0, _xlpm.x)*AU57/$AQ$3) -> 0 | BH57: 0 | BI57: =_xlfn.LET(_xlpm.x, _xlfn.XLOOKUP($Q57, $L$4:$N$4, $L57:$N57), IF(ISERROR(_xlpm.x), 0, _xlpm.x)*AV57/$AQ$3) -> 0 | BJ57: 0 | BK57: =_xlfn.LET(_xlpm.x, _xlfn.XLOOKUP($Q57, $L$4:$N$4, $L57:$N57), IF(ISERROR(_xlpm.x), 0, _xlpm.x)*AW57/$AQ$3) -> 0 | BL57: 0 | BM57: =_xlfn.LET(_xlpm.x, _xlfn.XLOOKUP($Q57, $L$4:$N$4, $L57:$N57), IF(ISERROR(_xlpm.x), 0, _xlpm.x)*AX57/$AQ$3) -> 0 | BN57: 0
A58: 9000 | B58: 10000 | C58: 11 | F58: 51422800 | I58: 1.1191737e-07 | J58: #DIV/0! | L58: #N/A | M58: #N/A | P58: ="("&$A58&", "&$B58&"]" -> (9000, 10000] | Q58: A | R58: =_xlfn.SINGLE(_xlfn.XLOOKUP(Q58, $I$4:$K$4, I58:K58)) -> 1.1191737e-07 | S58: 0 | T58: 0 | U58: 0 | V58: 0 | W58: 0 | X58: 0 | Y58: 0 | Z58: 0 | AA58: 0 | AB58: 0 | AC58: 0 | AD58: 0 | AE58: 0 | AF58: 0 | AG58: 0 | AH58: 0 | AI58: 0 | AJ58: 0 | AK58: 0 | AL58: 0 | AM58: 0 | AN58: 0 | AO58: 0 | AP58: 0 | AQ58: 0 | AR58: 0 | AS58: 0 | AT58: 0 | AU58: 0 | AV58: 0 | AW58: 0 | AX58: 0 | AY58: =_xlfn.LET(_xlpm.x, _xlfn.XLOOKUP($Q58, $L$4:$N$4, $L58:$N58), IF(ISERROR(_xlpm.x), 0, _xlpm.x)*AQ58/$AQ$3) -> 0 | AZ58: 0 | BA58: =_xlfn.LET(_xlpm.x, _xlfn.XLOOKUP($Q58, $L$4:$N$4, $L58:$N58), IF(ISERROR(_xlpm.x), 0, _xlpm.x)*AR58/$AQ$3) -> 0 | BB58: 0 | BC58: =_xlfn.LET(_xlpm.x, _xlfn.XLOOKUP($Q58, $L$4:$N$4, $L58:$N58), IF(ISERROR(_xlpm.x), 0, _xlpm.x)*AS58/$AQ$3) -> 0 | BD58: 0 | BE58: =_xlfn.LET(_xlpm.x, _xlfn.XLOOKUP($Q58, $L$4:$N$4, $L58:$N58), IF(ISERROR(_xlpm.x), 0, _xlpm.x)*AT58/$AQ$3) -> 0 | BF58: 0 | BG58: =_xlfn.LET(_xlpm.x, _xlfn.XLOOKUP($Q58, $L$4:$N$4, $L58:$N58), IF(ISERROR(_xlpm.x), 0, _xlpm.x)*AU58/$AQ$3) -> 0 | BH58: 0 | BI58: =_xlfn.LET(_xlpm.x, _xlfn.XLOOKUP($Q58, $L$4:$N$4, $L58:$N58), IF(ISERROR(_xlpm.x), 0, _xlpm.x)*AV58/$AQ$3) -> 0 | BJ58: 0 | BK58: =_xlfn.LET(_xlpm.x, _xlfn.XLOOKUP($Q58, $L$4:$N$4, $L58:$N58), IF(ISERROR(_xlpm.x), 0, _xlpm.x)*AW58/$AQ$3) -> 0 | BL58: 0 | BM58: =_xlfn.LET(_xlpm.x, _xlfn.XLOOKUP($Q58, $L$4:$N$4, $L58:$N58), IF(ISERROR(_xlpm.x), 0, _xlpm.x)*AX58/$AQ$3) -> 0 | BN58: 0
A59: 10000 | B59: 15000 | C59: 13 | F59: 76842925 | I59: 1.3226599e-07 | J59: #DIV/0! | L59: #N/A | M59: #N/A | P59: ="("&$A59&", "&$B59&"]" -> (10000, 15000] | Q59: A | R59: =_xlfn.SINGLE(_xlfn.XLOOKUP(Q59, $I$4:$K$4, I59:K59)) -> 1.3226599e-07 | S59: 0 | T59: 0 | U59: 0 | V59: 0 | W59: 0 | X59: 0 | Y59: 0 | Z59: 0 | AA59: 0 | AB59: 0 | AC59: 0 | AD59: 0 | AE59: 0 | AF59: 0 | AG59: 0 | AH59: 0 | AI59: 0 | AJ59: 0 | AK59: 0 | AL59: 0 | AM59: 0 | AN59: 0 | AO59: 0 | AP59: 0 | AQ59: 0 | AR59: 0 | AS59: 0 | AT59: 0 | AU59: 0 | AV59: 0 | AW59: 0 | AX59: 0 | AY59: =_xlfn.LET(_xlpm.x, _xlfn.XLOOKUP($Q59, $L$4:$N$4, $L59:$N59), IF(ISERROR(_xlpm.x), 0, _xlpm.x)*AQ59/$AQ$3) -> 0 | AZ59: 0 | BA59: =_xlfn.LET(_xlpm.x, _xlfn.XLOOKUP($Q59, $L$4:$N$4, $L59:$N59), IF(ISERROR(_xlpm.x), 0, _xlpm.x)*AR59/$AQ$3) -> 0 | BB59: 0 | BC59: =_xlfn.LET(_xlpm.x, _xlfn.XLOOKUP($Q59, $L$4:$N$4, $L59:$N59), IF(ISERROR(_xlpm.x), 0, _xlpm.x)*AS59/$AQ$3) -> 0 | BD59: 0 | BE59: =_xlfn.LET(_xlpm.x, _xlfn.XLOOKUP($Q59, $L$4:$N$4, $L59:$N59), IF(ISERROR(_xlpm.x), 0, _xlpm.x)*AT59/$AQ$3) -> 0 | BF59: 0 | BG59: =_xlfn.LET(_xlpm.x, _xlfn.XLOOKUP($Q59, $L$4:$N$4, $L59:$N59), IF(ISERROR(_xlpm.x), 0, _xlpm.x)*AU59/$AQ$3) -> 0 | BH59: 0 | BI59: =_xlfn.LET(_xlpm.x, _xlfn.XLOOKUP($Q59, $L$4:$N$4, $L59:$N59), IF(ISERROR(_xlpm.x), 0, _xlpm.x)*AV59/$AQ$3) -> 0 | BJ59: 0 | BK59: =_xlfn.LET(_xlpm.x, _xlfn.XLOOKUP($Q59, $L$4:$N$4, $L59:$N59), IF(ISERROR(_xlpm.x), 0, _xlpm.x)*AW59/$AQ$3) -> 0 | BL59: 0 | BM59: =_xlfn.LET(_xlpm.x, _xlfn.XLOOKUP($Q59, $L$4:$N$4, $L59:$N59), IF(ISERROR(_xlpm.x), 0, _xlpm.x)*AX59/$AQ$3) -> 0 | BN59: 0
A60: 15000 | B60: 20000 | C60: 2 | F60: 16729500 | I60: 2.0348613e-08 | J60: #DIV/0! | L60: #N/A | M60: #N/A | P60: ="("&$A60&", "&$B60&"]" -> (15000, 20000] | Q60: A | R60: =_xlfn.SINGLE(_xlfn.XLOOKUP(Q60, $I$4:$K$4, I60:K60)) -> 2.0348613e-08 | S60: 0 | T60: 0 | U60: 0 | V60: 0 | W60: 0 | X60: 0 | Y60: 0 | Z60: 0 | AA60: 0 | AB60: 0 | AC60: 0 | AD60: 0 | AE60: 0 | AF60: 0 | AG60: 0 | AH60: 0 | AI60: 0 | AJ60: 0 | AK60: 0 | AL60: 0 | AM60: 0 | AN60: 0 | AO60: 0 | AP60: 0 | AQ60: 0 | AR60: 0 | AS60: 0 | AT60: 0 | AU60: 0 | AV60: 0 | AW60: 0 | AX60: 0 | AY60: =_xlfn.LET(_xlpm.x, _xlfn.XLOOKUP($Q60, $L$4:$N$4, $L60:$N60), IF(ISERROR(_xlpm.x), 0, _xlpm.x)*AQ60/$AQ$3) -> 0 | AZ60: 0 | BA60: =_xlfn.LET(_xlpm.x, _xlfn.XLOOKUP($Q60, $L$4:$N$4, $L60:$N60), IF(ISERROR(_xlpm.x), 0, _xlpm.x)*AR60/$AQ$3) -> 0 | BB60: 0 | BC60: =_xlfn.LET(_xlpm.x, _xlfn.XLOOKUP($Q60, $L$4:$N$4, $L60:$N60), IF(ISERROR(_xlpm.x), 0, _xlpm.x)*AS60/$AQ$3) -> 0 | BD60: 0 | BE60: =_xlfn.LET(_xlpm.x, _xlfn.XLOOKUP($Q60, $L$4:$N$4, $L60:$N60), IF(ISERROR(_xlpm.x), 0, _xlpm.x)*AT60/$AQ$3) -> 0 | BF60: 0 | BG60: =_xlfn.LET(_xlpm.x, _xlfn.XLOOKUP($Q60, $L$4:$N$4, $L60:$N60), IF(ISERROR(_xlpm.x), 0, _xlpm.x)*AU60/$AQ$3) -> 0 | BH60: 0 | BI60: =_xlfn.LET(_xlpm.x, _xlfn.XLOOKUP($Q60, $L$4:$N$4, $L60:$N60), IF(ISERROR(_xlpm.x), 0, _xlpm.x)*AV60/$AQ$3) -> 0 | BJ60: 0 | BK60: =_xlfn.LET(_xlpm.x, _xlfn.XLOOKUP($Q60, $L$4:$N$4, $L60:$N60), IF(ISERROR(_xlpm.x), 0, _xlpm.x)*AW60/$AQ$3) -> 0 | BL60: 0 | BM60: =_xlfn.LET(_xlpm.x, _xlfn.XLOOKUP($Q60, $L$4:$N$4, $L60:$N60), IF(ISERROR(_xlpm.x), 0, _xlpm.x)*AX60/$AQ$3) -> 0 | BN60: 0
A61: 20000 | B61: 25000 | I61: 0 | J61: #DIV/0! | L61: #N/A | M61: #N/A | P61: ="("&$A61&", "&$B61&"]" -> (20000, 25000] | Q61: A | R61: =_xlfn.SINGLE(_xlfn.XLOOKUP(Q61, $I$4:$K$4, I61:K61)) -> 0 | S61: 0 | T61: 0 | U61: 0 | V61: 0 | W61: 0 | X61: 0 | Y61: 0 | Z61: 0 | AA61: 0 | AB61: 0 | AC61: 0 | AD61: 0 | AE61: 0 | AF61: 0 | AG61: 0 | AH61: 0 | AI61: 0 | AJ61: 0 | AK61: 0 | AL61: 0 | AM61: 0 | AN61: 0 | AO61: 0 | AP61: 0 | AQ61: 0 | AR61: 0 | AS61: 0 | AT61: 0 | AU61: 0 | AV61: 0 | AW61: 0 | AX61: 0 | AY61: =_xlfn.LET(_xlpm.x, _xlfn.XLOOKUP($Q61, $L$4:$N$4, $L61:$N61), IF(ISERROR(_xlpm.x), 0, _xlpm.x)*AQ61/$AQ$3) -> 0 | AZ61: 0 | BA61: =_xlfn.LET(_xlpm.x, _xlfn.XLOOKUP($Q61, $L$4:$N$4, $L61:$N61), IF(ISERROR(_xlpm.x), 0, _xlpm.x)*AR61/$AQ$3) -> 0 | BB61: 0 | BC61: =_xlfn.LET(_xlpm.x, _xlfn.XLOOKUP($Q61, $L$4:$N$4, $L61:$N61), IF(ISERROR(_xlpm.x), 0, _xlpm.x)*AS61/$AQ$3) -> 0 | BD61: 0 | BE61: =_xlfn.LET(_xlpm.x, _xlfn.XLOOKUP($Q61, $L$4:$N$4, $L61:$N61), IF(ISERROR(_xlpm.x), 0, _xlpm.x)*AT61/$AQ$3) -> 0 | BF61: 0 | BG61: =_xlfn.LET(_xlpm.x, _xlfn.XLOOKUP($Q61, $L$4:$N$4, $L61:$N61), IF(ISERROR(_xlpm.x), 0, _xlpm.x)*AU61/$AQ$3) -> 0 | BH61: 0 | BI61: =_xlfn.LET(_xlpm.x, _xlfn.XLOOKUP($Q61, $L$4:$N$4, $L61:$N61), IF(ISERROR(_xlpm.x), 0, _xlpm.x)*AV61/$AQ$3) -> 0 | BJ61: 0 | BK61: =_xlfn.LET(_xlpm.x, _xlfn.XLOOKUP($Q61, $L$4:$N$4, $L61:$N61), IF(ISERROR(_xlpm.x), 0, _xlpm.x)*AW61/$AQ$3) -> 0 | BL61: 0 | BM61: =_xlfn.LET(_xlpm.x, _xlfn.XLOOKUP($Q61, $L$4:$N$4, $L61:$N61), IF(ISERROR(_xlpm.x), 0, _xlpm.x)*AX61/$AQ$3) -> 0 | BN61: 0
A62: FG Trigger | B62: =C62/SUM(C5:C62) -> 0.01713207 | C62: 1713207 | F62: 4170765825 | P62: FG Trigger | Q62: A | R62: =0.00849 -> 0.00849 | S62: 0.4 | T62: 0.35 | U62: 0.8 | V62: 0.7 | W62: 0.4 | X62: 0.35 | Y62: 0.8 | Z62: 0.7 | AA62: 0.003396 | AB62: 0.0029715 | AC62: 0.006792 | AD62: 0.005943 | AE62: 0.003396 | AF62: 0.0029715 | AG62: 0.006792 | AH62: 0.005943 | AI62: =AA62 -> 0.003396 | AJ62: =AB62 -> 0.0029715 | AK62: =AC62 -> 0.006792 | AL62: =AD62 -> 0.005943 | AM62: =AE62 -> 0.003396 | AN62: =AF62 -> 0.0029715 | AO62: =AG62 -> 0.006792 | AP62: =AH62 -> 0.005943 | AQ62: 3396000 | AR62: 2971500 | AS62: 6792000 | AT62: 5943000 | AU62: 3396000 | AV62: 2971500 | AW62: 6792000 | AX62: 5943000 | AY62: =F62/C62/500*AQ62/AQ3 -> 0.016534979 | AZ62: 0.003396 | BA62: =F62/C62/500*AR62/AQ3 -> 0.014468106 | BB62: 0.0029715 | BC62: =F62/C62/500*AS62/AQ3 -> 0.033069958 | BD62: 0.006792 | BE62: =F62/C62/500*AT62/AQ3 -> 0.028936213 | BF62: 0.005943 | BG62: =F62/C62/500*AU62/AQ3 -> 0.016534979 | BH62: 0.003396 | BI62: =F62/C62/500*AV62/AQ3 -> 0.014468106 | BJ62: 0.0029715 | BK62: =F62/C62/500*AW62/AQ3 -> 0.033069958 | BL62: 0.006792 | BM62: =F62/C62/500*AX62/AQ3 -> 0.028936213 | BN62: 0.005943
F63: =SUM(F5:F56)/10^8/500 -> 2.7508935
AZ64: 新手(A) | BB64: 老手(A) | BD64: 新手 (EX)(A) | BF64: 老手 (EX)(A) | BH64: 新手(B) | BJ64: 老手(B) | BL64: 新手 (EX)(B) | BN64: 老手 (EX)(B)
A65: Lower | B65: Upper | C65: Simulator Cnt | F65: Simulator Pay | I65: Simulator Rate | L65: Simulator RTP | P65: Range | Q65: Free Game | AI65: Threshold | AQ65: =10^9 -> 1000000000 | AY65: Free Game 1 RTP | AZ65: =SUM(AY67:AY125)*AZ62 -> 0.45958288 | BA65: Free Game 2 RTP | BB65: =SUM(BA67:BA125)*BB62 -> 0.48469981 | BC65: Free Game 3 RTP | BD65: =SUM(BC67:BC125)*BD62 -> 0.91916575 | BE65: Free Game 3 RTP | BF65: =SUM(BE67:BE125)*BF62 -> 0.96939963 | BG65: Free Game 1 RTP | BH65: =SUM(BG67:BG125)*BH62 -> 0.46310943 | BI65: Free Game 2 RTP | BJ65: =SUM(BI67:BI125)*BJ62 -> 0.47249529 | BK65: Free Game 3 RTP | BL65: =SUM(BK67:BK125)*BL62 -> 0.92621885 | BM65: Free Game 3 RTP | BN65: =SUM(BM67:BM125)*BN62 -> 0.94499058
C66: D | D66: E | E66: F | F66: D | G66: E | H66: F | I66: D | J66: E | K66: F | L66: D | M66: E | N66: F | Q66: 使用的表 | R66: Rate | S66: Fix Num 1 | T66: Fix Num 2 | U66: Fix Num 3 | V66: Fix Num 4 | W66: Fix Num 5 | X66: Fix Num 6 | Y66: Fix Num 7 | Z66: Fix Num 8 | AA66: Fix Rate 1 | AB66: Fix Rate 2 | AC66: Fix Rate 3 | AD66: Fix Rate 4 | AE66: Fix Rate 5 | AF66: Fix Rate 6 | AG66: Fix Rate 7 | AH66: Fix Rate 8 | AI66: Final Rate 1 | AJ66: Final Rate 2 | AK66: Final Rate 3 | AL66: Final Rate 4 | AM66: Final Rate 5 | AN66: Final Rate 6 | AO66: Final Rate 7 | AP66: Final Rate 8 | AQ66: Weight 1 | AR66: Weight 2 | AS66: Weight 3 | AT66: Weight 4 | AU66: Weight 5 | AV66: Weight 6 | AW66: Weight 7 | AX66: Weight 8 | AY66: Simulator RTP | AZ66: Hit Rate | BA66: Simulator RTP | BB66: Hit Rate | BC66: Simulator RTP | BD66: Hit Rate | BE66: Simulator RTP | BF66: Hit Rate | BG66: Simulator RTP | BH66: Hit Rate | BI66: Simulator RTP | BJ66: Hit Rate | BK66: Simulator RTP | BL66: Hit Rate | BM66: Simulator RTP | BN66: Hit Rate | BP66: Sugar Rush
A67: -1 | B67: 0 | C67: 18 | F67: 0 | I67: {=_xlfn.LET(_xlpm.x, C67:C125, _xlpm.x/SUM(_xlpm.x))} -> 1.0506611e-05 | J67: {=_xlfn.LET(_xlpm.x, D67:D125, _xlpm.x/SUM(_xlpm.x))} -> #DIV/0! | L67: {=F67:F125/C67:C125/Overview!$A$5/5} -> 0 | M67: {=G67:G125/D67:D125/Overview!$A$5/5} -> #DIV/0! | P67: ="("&$A67&", "&$B67&"]" -> (-1, 0] | Q67: D | R67: =_xlfn.SINGLE(_xlfn.XLOOKUP(Q67, $I$66:$K$66, I67:K67)) -> 1.0506611e-05 | S67: 0 | T67: 0 | U67: 0 | V67: 0 | W67: 0 | X67: 0 | Y67: 0 | Z67: 0 | AA67: {=$R67:$R125*S67:S125} -> 0 | AB67: {=$R67:$R125*T67:T125} -> 0 | AC67: {=$R67:$R125*U67:U125} -> 0 | AD67: {=$R67:$R125*V67:V125} -> 0 | AE67: {=$R67:$R125*W67:W125} -> 0 | AF67: {=$R67:$R125*X67:X125} -> 0 | AG67: {=$R67:$R125*Y67:Y125} -> 0 | AH67: {=$R67:$R125*Z67:Z125} -> 0 | AI67: {=_xlfn.LET(_xlpm.x,_xlfn.ANCHORARRAY( AA67), _xlpm.x/SUM(_xlpm.x))} -> 0 | AJ67: {=_xlfn.LET(_xlpm.x,_xlfn.ANCHORARRAY( AB67), _xlpm.x/SUM(_xlpm.x))} -> 0 | AK67: {=_xlfn.LET(_xlpm.x,_xlfn.ANCHORARRAY( AC67), _xlpm.x/SUM(_xlpm.x))} -> 0 | AL67: {=_xlfn.LET(_xlpm.x,_xlfn.ANCHORARRAY( AD67), _xlpm.x/SUM(_xlpm.x))} -> 0 | AM67: {=_xlfn.LET(_xlpm.x,_xlfn.ANCHORARRAY( AE67), _xlpm.x/SUM(_xlpm.x))} -> 0 | AN67: {=_xlfn.LET(_xlpm.x,_xlfn.ANCHORARRAY( AF67), _xlpm.x/SUM(_xlpm.x))} -> 0 | AO67: {=_xlfn.LET(_xlpm.x,_xlfn.ANCHORARRAY( AG67), _xlpm.x/SUM(_xlpm.x))} -> 0 | AP67: {=_xlfn.LET(_xlpm.x,_xlfn.ANCHORARRAY( AH67), _xlpm.x/SUM(_xlpm.x))} -> 0 | AQ67: =INT(AI67*$AQ$65) -> 0 | AR67: =INT(AJ67*$AQ$65) -> 0 | AS67: =INT(AK67*$AQ$65) -> 0 | AT67: =INT(AL67*$AQ$65) -> 0 | AU67: =INT(AM67*$AQ$65) -> 0 | AV67: =INT(AN67*$AQ$65) -> 0 | AW67: =INT(AO67*$AQ$65) -> 0 | AX67: =INT(AP67*$AQ$65) -> 0 | AY67: =_xlfn.LET(_xlpm.x, _xlfn.XLOOKUP($Q67, $L$66:$N$66, $L67:$N67), IF(ISERROR(_xlpm.x), 0, _xlpm.x)*AQ67/$AQ$65) -> 0 | AZ67: {=_xlfn.LET(_xlpm.x, AQ67:AQ125, _xlpm.x/SUM(_xlpm.x))} -> 0 | BA67: =_xlfn.LET(_xlpm.x, _xlfn.XLOOKUP($Q67, $L$66:$N$66, $L67:$N67), IF(ISERROR(_xlpm.x), 0, _xlpm.x)*AR67/$AQ$65) -> 0 | BB67: {=_xlfn.LET(_xlpm.x, AR67:AR125, _xlpm.x/SUM(_xlpm.x))} -> 0 | BC67: =_xlfn.LET(_xlpm.x, _xlfn.XLOOKUP($Q67, $L$66:$N$66, $L67:$N67), IF(ISERROR(_xlpm.x), 0, _xlpm.x)*AS67/$AQ$65) -> 0 | BD67: {=_xlfn.LET(_xlpm.x, AS67:AS125, _xlpm.x/SUM(_xlpm.x))} -> 0 | BE67: =_xlfn.LET(_xlpm.x, _xlfn.XLOOKUP($Q67, $L$66:$N$66, $L67:$N67), IF(ISERROR(_xlpm.x), 0, _xlpm.x)*AT67/$AQ$65) -> 0 | BF67: {=_xlfn.LET(_xlpm.x, AT67:AT125, _xlpm.x/SUM(_xlpm.x))} -> 0 | BG67: =_xlfn.LET(_xlpm.x, _xlfn.XLOOKUP($Q67, $L$66:$N$66, $L67:$N67), IF(ISERROR(_xlpm.x), 0, _xlpm.x)*AU67/$AQ$65) -> 0 | BH67: {=_xlfn.LET(_xlpm.x, AU67:AU125, _xlpm.x/SUM(_xlpm.x))} -> 0 | BI67: =_xlfn.LET(_xlpm.x, _xlfn.XLOOKUP($Q67, $L$66:$N$66, $L67:$N67), IF(ISERROR(_xlpm.x), 0, _xlpm.x)*AV67/$AQ$65) -> 0 | BJ67: {=_xlfn.LET(_xlpm.x, AV67:AV125, _xlpm.x/SUM(_xlpm.x))} -> 0 | BK67: =_xlfn.LET(_xlpm.x, _xlfn.XLOOKUP($Q67, $L$66:$N$66, $L67:$N67), IF(ISERROR(_xlpm.x), 0, _xlpm.x)*AW67/$AQ$65) -> 0 | BL67: {=_xlfn.LET(_xlpm.x, AW67:AW125, _xlpm.x/SUM(_xlpm.x))} -> 0 | BM67: =_xlfn.LET(_xlpm.x, _xlfn.XLOOKUP($Q67, $L$66:$N$66, $L67:$N67), IF(ISERROR(_xlpm.x), 0, _xlpm.x)*AX67/$AQ$65) -> 0 | BN67: {=_xlfn.LET(_xlpm.x, AX67:AX125, _xlpm.x/SUM(_xlpm.x))} -> 0 | BP67: 0
A68: 0 | B68: 1 | C68: 495 | F68: 180175 | I68: 0.00028893181 | J68: #DIV/0! | L68: 1.4559596 | M68: #DIV/0! | P68: ="("&$A68&", "&$B68&"]" -> (0, 1] | Q68: D | R68: =_xlfn.SINGLE(_xlfn.XLOOKUP(Q68, $I$66:$K$66, I68:K68)) -> 0.00028893181 | S68: 0 | T68: 0 | U68: 0 | V68: 0 | W68: 0 | X68: 0 | Y68: 0 | Z68: 0 | AA68: 0 | AB68: 0 | AC68: 0 | AD68: 0 | AE68: 0 | AF68: 0 | AG68: 0 | AH68: 0 | AI68: 0 | AJ68: 0 | AK68: 0 | AL68: 0 | AM68: 0 | AN68: 0 | AO68: 0 | AP68: 0 | AQ68: =INT(AI68*$AQ$65) -> 0 | AR68: =INT(AJ68*$AQ$65) -> 0 | AS68: =INT(AK68*$AQ$65) -> 0 | AT68: =INT(AL68*$AQ$65) -> 0 | AU68: =INT(AM68*$AQ$65) -> 0 | AV68: =INT(AN68*$AQ$65) -> 0 | AW68: =INT(AO68*$AQ$65) -> 0 | AX68: =INT(AP68*$AQ$65) -> 0 | AY68: =_xlfn.LET(_xlpm.x, _xlfn.XLOOKUP($Q68, $L$66:$N$66, $L68:$N68), IF(ISERROR(_xlpm.x), 0, _xlpm.x)*AQ68/$AQ$65) -> 0 | AZ68: 0 | BA68: =_xlfn.LET(_xlpm.x, _xlfn.XLOOKUP($Q68, $L$66:$N$66, $L68:$N68), IF(ISERROR(_xlpm.x), 0, _xlpm.x)*AR68/$AQ$65) -> 0 | BB68: 0 | BC68: =_xlfn.LET(_xlpm.x, _xlfn.XLOOKUP($Q68, $L$66:$N$66, $L68:$N68), IF(ISERROR(_xlpm.x), 0, _xlpm.x)*AS68/$AQ$65) -> 0 | BD68: 0 | BE68: =_xlfn.LET(_xlpm.x, _xlfn.XLOOKUP($Q68, $L$66:$N$66, $L68:$N68), IF(ISERROR(_xlpm.x), 0, _xlpm.x)*AT68/$AQ$65) -> 0 | BF68: 0 | BG68: =_xlfn.LET(_xlpm.x, _xlfn.XLOOKUP($Q68, $L$66:$N$66, $L68:$N68), IF(ISERROR(_xlpm.x), 0, _xlpm.x)*AU68/$AQ$65) -> 0 | BH68: 0 | BI68: =_xlfn.LET(_xlpm.x, _xlfn.XLOOKUP($Q68, $L$66:$N$66, $L68:$N68), IF(ISERROR(_xlpm.x), 0, _xlpm.x)*AV68/$AQ$65) -> 0 | BJ68: 0 | BK68: =_xlfn.LET(_xlpm.x, _xlfn.XLOOKUP($Q68, $L$66:$N$66, $L68:$N68), IF(ISERROR(_xlpm.x), 0, _xlpm.x)*AW68/$AQ$65) -> 0 | BL68: 0 | BM68: =_xlfn.LET(_xlpm.x, _xlfn.XLOOKUP($Q68, $L$66:$N$66, $L68:$N68), IF(ISERROR(_xlpm.x), 0, _xlpm.x)*AX68/$AQ$65) -> 0 | BN68: 0 | BP68: 0.015625
A69: 1 | B69: 2 | C69: 2473 | F69: 2003975 | I69: 0.0014434917 | J69: #DIV/0! | L69: 3.2413668 | M69: #DIV/0! | P69: ="("&$A69&", "&$B69&"]" -> (1, 2] | Q69: D | R69: =_xlfn.SINGLE(_xlfn.XLOOKUP(Q69, $I$66:$K$66, I69:K69)) -> 0.0014434917 | S69: 0 | T69: 10.208718 | U69: 0 | V69: 10.208718 | W69: 0 | X69: 0 | Y69: 0 | Z69: 0 | AA69: 0 | AB69: 0.014736199 | AC69: 0 | AD69: 0.014736199 | AE69: 0 | AF69: 0 | AG69: 0 | AH69: 0 | AI69: 0 | AJ69: 0.01408617 | AK69: 0 | AL69: 0.01408617 | AM69: 0 | AN69: 0 | AO69: 0 | AP69: 0 | AQ69: =INT(AI69*$AQ$65) -> 0 | AR69: =INT(AJ69*$AQ$65) -> 14086170 | AS69: =INT(AK69*$AQ$65) -> 0 | AT69: =INT(AL69*$AQ$65) -> 14086170 | AU69: =INT(AM69*$AQ$65) -> 0 | AV69: =INT(AN69*$AQ$65) -> 0 | AW69: =INT(AO69*$AQ$65) -> 0 | AX69: =INT(AP69*$AQ$65) -> 0 | AY69: =_xlfn.LET(_xlpm.x, _xlfn.XLOOKUP($Q69, $L$66:$N$66, $L69:$N69), IF(ISERROR(_xlpm.x), 0, _xlpm.x)*AQ69/$AQ$65) -> 0 | AZ69: 0 | BA69: =_xlfn.LET(_xlpm.x, _xlfn.XLOOKUP($Q69, $L$66:$N$66, $L69:$N69), IF(ISERROR(_xlpm.x), 0, _xlpm.x)*AR69/$AQ$65) -> 0.045658443 | BB69: 0.01408617 | BC69: =_xlfn.LET(_xlpm.x, _xlfn.XLOOKUP($Q69, $L$66:$N$66, $L69:$N69), IF(ISERROR(_xlpm.x), 0, _xlpm.x)*AS69/$AQ$65) -> 0 | BD69: 0 | BE69: =_xlfn.LET(_xlpm.x, _xlfn.XLOOKUP($Q69, $L$66:$N$66, $L69:$N69), IF(ISERROR(_xlpm.x), 0, _xlpm.x)*AT69/$AQ$65) -> 0.045658443 | BF69: 0.01408617 | BG69: =_xlfn.LET(_xlpm.x, _xlfn.XLOOKUP($Q69, $L$66:$N$66, $L69:$N69), IF(ISERROR(_xlpm.x), 0, _xlpm.x)*AU69/$AQ$65) -> 0 | BH69: 0 | BI69: =_xlfn.LET(_xlpm.x, _xlfn.XLOOKUP($Q69, $L$66:$N$66, $L69:$N69), IF(ISERROR(_xlpm.x), 0, _xlpm.x)*AV69/$AQ$65) -> 0 | BJ69: 0 | BK69: =_xlfn.LET(_xlpm.x, _xlfn.XLOOKUP($Q69, $L$66:$N$66, $L69:$N69), IF(ISERROR(_xlpm.x), 0, _xlpm.x)*AW69/$AQ$65) -> 0 | BL69: 0 | BM69: =_xlfn.LET(_xlpm.x, _xlfn.XLOOKUP($Q69, $L$66:$N$66, $L69:$N69), IF(ISERROR(_xlpm.x), 0, _xlpm.x)*AX69/$AQ$65) -> 0 | BN69: 0 | BP69: 0.015625
A70: 2 | B70: 3 | C70: 5491 | F70: 7071425 | I70: 0.0032051001 | J70: #DIV/0! | L70: 5.1512839 | M70: #DIV/0! | P70: ="("&$A70&", "&$B70&"]" -> (2, 3] | Q70: D | R70: =_xlfn.SINGLE(_xlfn.XLOOKUP(Q70, $I$66:$K$66, I70:K70)) -> 0.0032051001 | S70: 0 | T70: 4.6404996 | U70: 0 | V70: 4.6404996 | W70: 0 | X70: 0 | Y70: 0 | Z70: 0 | AA70: 0 | AB70: 0.014873266 | AC70: 0 | AD70: 0.014873266 | AE70: 0 | AF70: 0 | AG70: 0 | AH70: 0 | AI70: 0 | AJ70: 0.014217191 | AK70: 0 | AL70: 0.014217191 | AM70: 0 | AN70: 0 | AO70: 0 | AP70: 0 | AQ70: =INT(AI70*$AQ$65) -> 0 | AR70: =INT(AJ70*$AQ$65) -> 14217190 | AS70: =INT(AK70*$AQ$65) -> 0 | AT70: =INT(AL70*$AQ$65) -> 14217190 | AU70: =INT(AM70*$AQ$65) -> 0 | AV70: =INT(AN70*$AQ$65) -> 0 | AW70: =INT(AO70*$AQ$65) -> 0 | AX70: =INT(AP70*$AQ$65) -> 0 | AY70: =_xlfn.LET(_xlpm.x, _xlfn.XLOOKUP($Q70, $L$66:$N$66, $L70:$N70), IF(ISERROR(_xlpm.x), 0, _xlpm.x)*AQ70/$AQ$65) -> 0 | AZ70: 0 | BA70: =_xlfn.LET(_xlpm.x, _xlfn.XLOOKUP($Q70, $L$66:$N$66, $L70:$N70), IF(ISERROR(_xlpm.x), 0, _xlpm.x)*AR70/$AQ$65) -> 0.073236782 | BB70: 0.01421719 | BC70: =_xlfn.LET(_xlpm.x, _xlfn.XLOOKUP($Q70, $L$66:$N$66, $L70:$N70), IF(ISERROR(_xlpm.x), 0, _xlpm.x)*AS70/$AQ$65) -> 0 | BD70: 0 | BE70: =_xlfn.LET(_xlpm.x, _xlfn.XLOOKUP($Q70, $L$66:$N$66, $L70:$N70), IF(ISERROR(_xlpm.x), 0, _xlpm.x)*AT70/$AQ$65) -> 0.073236782 | BF70: 0.01421719 | BG70: =_xlfn.LET(_xlpm.x, _xlfn.XLOOKUP($Q70, $L$66:$N$66, $L70:$N70), IF(ISERROR(_xlpm.x), 0, _xlpm.x)*AU70/$AQ$65) -> 0 | BH70: 0 | BI70: =_xlfn.LET(_xlpm.x, _xlfn.XLOOKUP($Q70, $L$66:$N$66, $L70:$N70), IF(ISERROR(_xlpm.x), 0, _xlpm.x)*AV70/$AQ$65) -> 0 | BJ70: 0 | BK70: =_xlfn.LET(_xlpm.x, _xlfn.XLOOKUP($Q70, $L$66:$N$66, $L70:$N70), IF(ISERROR(_xlpm.x), 0, _xlpm.x)*AW70/$AQ$65) -> 0 | BL70: 0 | BM70: =_xlfn.LET(_xlpm.x, _xlfn.XLOOKUP($Q70, $L$66:$N$66, $L70:$N70), IF(ISERROR(_xlpm.x), 0, _xlpm.x)*AX70/$AQ$65) -> 0 | BN70: 0 | BP70: 0.015625
